<?xml version="0.0" ?>
<robot name="go2">
	<link name="base">
		<inertial>
			<origin rpy="0.00000 0.00000 0.00000" xyz="0.02111 0.00000 -0.00537"/>
			<mass value="6.92100"/>
			<inertia ixx="0.02448" ixy="0.00012" ixz="0.00148" iyy="0.09808" iyz="-0.00003" izz="0.10700"/>
		</inertial>
		<visual>
			<origin rpy="0.00000 0.00000 0.00000" xyz="0.00000 0.00000 0.00000"/>
			<geometry>
				<box size="0.37620 0.09350 0.11400"/>
			</geometry>
			<material name="">
				<color rgba="0.00000 0.00000 0.00000 0.50000" />
			</material>
		</visual>
		<collision>
			<origin rpy="0.00000 0.00000 0.00000" xyz="0.00000 0.00000 0.00000"/>
			<geometry>
				<box size="0.37620 0.09350 0.11400"/>
			</geometry>
		</collision>
	</link>
	<link name="Head_upper">
		<inertial>
			<origin rpy="0.00000 0.00000 0.00000" xyz="0.00000 0.00000 0.00000"/>
			<mass value="0.00100"/>
			<inertia ixx="0.00001" ixy="0.00000" ixz="0.00000" iyy="0.00001" iyz="0.00000" izz="0.00001"/>
		</inertial>
		<visual>
			<origin rpy="0.00000 0.00000 0.00000" xyz="0.00000 0.00000 0.00000"/>
			<geometry>
				<cylinder length="0.09000" radius="0.05000"/>
			</geometry>
			<material name="">
				<color rgba="0.00000 0.00000 0.00000 0.50000" />
			</material>
		</visual>
		<collision>
			<origin rpy="0.00000 0.00000 0.00000" xyz="0.00000 0.00000 0.00000"/>
			<geometry>
				<cylinder length="0.09000" radius="0.05000"/>
			</geometry>
		</collision>
	</link>
	<link name="Head_lower">
		<inertial>
			<origin rpy="0.00000 0.00000 0.00000" xyz="0.00000 0.00000 0.00000"/>
			<mass value="0.00100"/>
			<inertia ixx="0.00001" ixy="0.00000" ixz="0.00000" iyy="0.00001" iyz="0.00000" izz="0.00001"/>
		</inertial>
		<visual>
			<origin rpy="0.00000 0.00000 0.00000" xyz="0.00000 0.00000 0.00000"/>
			<geometry>
				<sphere radius="0.04700"/>
			</geometry>
			<material name="">
				<color rgba="0.00000 0.00000 0.00000 0.50000" />
			</material>
		</visual>
		<collision>
			<origin rpy="0.00000 0.00000 0.00000" xyz="0.00000 0.00000 0.00000"/>
			<geometry>
				<sphere radius="0.04700"/>
			</geometry>
		</collision>
	</link>
	<link name="FL_hip">
		<inertial>
			<origin rpy="0.00000 0.00000 0.00000" xyz="-0.00540 0.00194 -0.00011"/>
			<mass value="0.67800"/>
			<inertia ixx="0.00048" ixy="-0.00000" ixz="0.00000" iyy="0.00088" iyz="-0.00000" izz="0.00060"/>
		</inertial>
		<visual>
			<origin rpy="1.57080 0.00000 0.00000" xyz="0.00000 0.08000 0.00000"/>
			<geometry>
				<cylinder length="0.04000" radius="0.04600"/>
			</geometry>
			<material name="">
				<color rgba="0.00000 0.00000 0.00000 0.50000" />
			</material>
		</visual>
		<collision>
			<origin rpy="1.57080 0.00000 0.00000" xyz="0.00000 0.08000 0.00000"/>
			<geometry>
				<cylinder length="0.04000" radius="0.04600"/>
			</geometry>
		</collision>
	</link>
	<link name="FL_thigh">
		<inertial>
			<origin rpy="0.00000 0.00000 0.00000" xyz="-0.00374 -0.02230 -0.03270"/>
			<mass value="1.15200"/>
			<inertia ixx="0.00584" ixy="0.00009" ixz="-0.00029" iyy="0.00580" iyz="0.00081" izz="0.00103"/>
		</inertial>
		<visual>
			<origin rpy="0.00000 1.57080 0.00000" xyz="0.00000 0.00000 -0.10650"/>
			<geometry>
				<box size="0.11000 0.02450 0.03400"/>
			</geometry>
			<material name="">
				<color rgba="0.00000 0.00000 0.00000 0.50000" />
			</material>
		</visual>
		<collision>
			<origin rpy="0.00000 1.57080 0.00000" xyz="0.00000 0.00000 -0.10650"/>
			<geometry>
				<box size="0.11000 0.02450 0.03400"/>
			</geometry>
		</collision>
	</link>
	<link name="FL_calf">
		<inertial>
			<origin rpy="0.00000 0.00000 0.00000" xyz="0.00548 -0.00097 -0.11500"/>
			<mass value="0.15400"/>
			<inertia ixx="0.00108" ixy="0.00000" ixz="0.00002" iyy="0.00110" iyz="0.00001" izz="0.00003"/>
		</inertial>
		<visual>
			<origin rpy="0.00000 -0.21000 0.00000" xyz="0.00800 0.00000 -0.06000"/>
			<geometry>
				<cylinder length="0.12000" radius="0.01200"/>
			</geometry>
			<material name="">
				<color rgba="0.00000 0.00000 0.00000 0.50000" />
			</material>
		</visual>
		<collision>
			<origin rpy="0.00000 -0.21000 0.00000" xyz="0.00800 0.00000 -0.06000"/>
			<geometry>
				<cylinder length="0.12000" radius="0.01200"/>
			</geometry>
		</collision>
	</link>
	<link name="FL_calflower">
		<inertial>
			<origin rpy="0.00000 0.00000 0.00000" xyz="0.00000 0.00000 0.00000"/>
			<mass value="0.00100"/>
			<inertia ixx="0.00001" ixy="0.00000" ixz="0.00000" iyy="0.00001" iyz="0.00000" izz="0.00001"/>
		</inertial>
		<visual>
			<origin rpy="0.00000 0.00000 0.00000" xyz="0.00000 0.00000 0.00000"/>
			<geometry>
				<cylinder length="0.06500" radius="0.01100"/>
			</geometry>
			<material name="">
				<color rgba="0.00000 0.00000 0.00000 0.50000" />
			</material>
		</visual>
		<collision>
			<origin rpy="0.00000 0.00000 0.00000" xyz="0.00000 0.00000 0.00000"/>
			<geometry>
				<cylinder length="0.06500" radius="0.01100"/>
			</geometry>
		</collision>
	</link>
	<link name="FL_calflower1">
		<inertial>
			<origin rpy="0.00000 0.00000 0.00000" xyz="0.00000 0.00000 0.00000"/>
			<mass value="0.00100"/>
			<inertia ixx="0.00001" ixy="0.00000" ixz="0.00000" iyy="0.00001" iyz="0.00000" izz="0.00001"/>
		</inertial>
		<visual>
			<origin rpy="0.00000 0.00000 0.00000" xyz="0.00000 0.00000 0.00000"/>
			<geometry>
				<cylinder length="0.03000" radius="0.01550"/>
			</geometry>
			<material name="">
				<color rgba="0.00000 0.00000 0.00000 0.50000" />
			</material>
		</visual>
		<collision>
			<origin rpy="0.00000 0.00000 0.00000" xyz="0.00000 0.00000 0.00000"/>
			<geometry>
				<cylinder length="0.03000" radius="0.01550"/>
			</geometry>
		</collision>
	</link>
	<link name="FL_foot">
		<inertial>
			<origin rpy="0.00000 0.00000 0.00000" xyz="0.00000 0.00000 0.00000"/>
			<mass value="0.04000"/>
			<inertia ixx="0.00001" ixy="0.00000" ixz="0.00000" iyy="0.00001" iyz="0.00000" izz="0.00001"/>
		</inertial>
		<visual>
			<origin rpy="0.00000 0.00000 0.00000" xyz="-0.00200 0.00000 0.00000"/>
			<geometry>
				<sphere radius="0.02200"/>
			</geometry>
			<material name="">
				<color rgba="0.00000 0.00000 0.00000 0.50000" />
			</material>
		</visual>
		<collision>
			<origin rpy="0.00000 0.00000 0.00000" xyz="-0.00200 0.00000 0.00000"/>
			<geometry>
				<sphere radius="0.02200"/>
			</geometry>
		</collision>
	</link>
	<link name="FR_hip">
		<inertial>
			<origin rpy="0.00000 0.00000 0.00000" xyz="-0.00540 -0.00194 -0.00011"/>
			<mass value="0.67800"/>
			<inertia ixx="0.00048" ixy="0.00000" ixz="0.00000" iyy="0.00088" iyz="0.00000" izz="0.00060"/>
		</inertial>
		<visual>
			<origin rpy="1.57080 0.00000 0.00000" xyz="0.00000 -0.08000 0.00000"/>
			<geometry>
				<cylinder length="0.04000" radius="0.04600"/>
			</geometry>
			<material name="">
				<color rgba="0.00000 0.00000 0.00000 0.50000" />
			</material>
		</visual>
		<collision>
			<origin rpy="1.57080 0.00000 0.00000" xyz="0.00000 -0.08000 0.00000"/>
			<geometry>
				<cylinder length="0.04000" radius="0.04600"/>
			</geometry>
		</collision>
	</link>
	<link name="FR_thigh">
		<inertial>
			<origin rpy="0.00000 0.00000 0.00000" xyz="-0.00374 0.02230 -0.03270"/>
			<mass value="1.15200"/>
			<inertia ixx="0.00584" ixy="-0.00009" ixz="-0.00029" iyy="0.00580" iyz="-0.00081" izz="0.00103"/>
		</inertial>
		<visual>
			<origin rpy="0.00000 1.57080 0.00000" xyz="0.00000 0.00000 -0.10650"/>
			<geometry>
				<box size="0.11000 0.02450 0.03400"/>
			</geometry>
			<material name="">
				<color rgba="0.00000 0.00000 0.00000 0.50000" />
			</material>
		</visual>
		<collision>
			<origin rpy="0.00000 1.57080 0.00000" xyz="0.00000 0.00000 -0.10650"/>
			<geometry>
				<box size="0.11000 0.02450 0.03400"/>
			</geometry>
		</collision>
	</link>
	<link name="FR_calf">
		<inertial>
			<origin rpy="0.00000 0.00000 0.00000" xyz="0.00548 0.00097 -0.11500"/>
			<mass value="0.15400"/>
			<inertia ixx="0.00108" ixy="-0.00000" ixz="0.00002" iyy="0.00110" iyz="-0.00001" izz="0.00003"/>
		</inertial>
		<visual>
			<origin rpy="0.00000 -0.20000 0.00000" xyz="0.01000 0.00000 -0.06000"/>
			<geometry>
				<cylinder length="0.12000" radius="0.01300"/>
			</geometry>
			<material name="">
				<color rgba="0.00000 0.00000 0.00000 0.50000" />
			</material>
		</visual>
		<collision>
			<origin rpy="0.00000 -0.20000 0.00000" xyz="0.01000 0.00000 -0.06000"/>
			<geometry>
				<cylinder length="0.12000" radius="0.01300"/>
			</geometry>
		</collision>
	</link>
	<link name="FR_calflower">
		<inertial>
			<origin rpy="0.00000 0.00000 0.00000" xyz="0.00000 0.00000 0.00000"/>
			<mass value="0.00100"/>
			<inertia ixx="0.00001" ixy="0.00000" ixz="0.00000" iyy="0.00001" iyz="0.00000" izz="0.00001"/>
		</inertial>
		<visual>
			<origin rpy="0.00000 0.00000 0.00000" xyz="0.00000 0.00000 0.00000"/>
			<geometry>
				<cylinder length="0.06500" radius="0.01100"/>
			</geometry>
			<material name="">
				<color rgba="0.00000 0.00000 0.00000 0.50000" />
			</material>
		</visual>
		<collision>
			<origin rpy="0.00000 0.00000 0.00000" xyz="0.00000 0.00000 0.00000"/>
			<geometry>
				<cylinder length="0.06500" radius="0.01100"/>
			</geometry>
		</collision>
	</link>
	<link name="FR_calflower1">
		<inertial>
			<origin rpy="0.00000 0.00000 0.00000" xyz="0.00000 0.00000 0.00000"/>
			<mass value="0.00100"/>
			<inertia ixx="0.00001" ixy="0.00000" ixz="0.00000" iyy="0.00001" iyz="0.00000" izz="0.00001"/>
		</inertial>
		<visual>
			<origin rpy="0.00000 0.00000 0.00000" xyz="0.00000 0.00000 0.00000"/>
			<geometry>
				<cylinder length="0.03000" radius="0.01550"/>
			</geometry>
			<material name="">
				<color rgba="0.00000 0.00000 0.00000 0.50000" />
			</material>
		</visual>
		<collision>
			<origin rpy="0.00000 0.00000 0.00000" xyz="0.00000 0.00000 0.00000"/>
			<geometry>
				<cylinder length="0.03000" radius="0.01550"/>
			</geometry>
		</collision>
	</link>
	<link name="FR_foot">
		<inertial>
			<origin rpy="0.00000 0.00000 0.00000" xyz="0.00000 0.00000 0.00000"/>
			<mass value="0.04000"/>
			<inertia ixx="0.00001" ixy="0.00000" ixz="0.00000" iyy="0.00001" iyz="0.00000" izz="0.00001"/>
		</inertial>
		<visual>
			<origin rpy="0.00000 0.00000 0.00000" xyz="-0.00200 0.00000 0.00000"/>
			<geometry>
				<sphere radius="0.02200"/>
			</geometry>
			<material name="">
				<color rgba="0.00000 0.00000 0.00000 0.50000" />
			</material>
		</visual>
		<collision>
			<origin rpy="0.00000 0.00000 0.00000" xyz="-0.00200 0.00000 0.00000"/>
			<geometry>
				<sphere radius="0.02200"/>
			</geometry>
		</collision>
	</link>
	<link name="RL_hip">
		<inertial>
			<origin rpy="0.00000 0.00000 0.00000" xyz="0.00540 0.00194 -0.00011"/>
			<mass value="0.67800"/>
			<inertia ixx="0.00048" ixy="0.00000" ixz="-0.00000" iyy="0.00088" iyz="-0.00000" izz="0.00060"/>
		</inertial>
		<visual>
			<origin rpy="1.57080 0.00000 0.00000" xyz="0.00000 0.08000 0.00000"/>
			<geometry>
				<cylinder length="0.04000" radius="0.04600"/>
			</geometry>
			<material name="">
				<color rgba="0.00000 0.00000 0.00000 0.50000" />
			</material>
		</visual>
		<collision>
			<origin rpy="1.57080 0.00000 0.00000" xyz="0.00000 0.08000 0.00000"/>
			<geometry>
				<cylinder length="0.04000" radius="0.04600"/>
			</geometry>
		</collision>
	</link>
	<link name="RL_thigh">
		<inertial>
			<origin rpy="0.00000 0.00000 0.00000" xyz="-0.00374 -0.02230 -0.03270"/>
			<mass value="1.15200"/>
			<inertia ixx="0.00584" ixy="0.00009" ixz="-0.00029" iyy="0.00580" iyz="0.00081" izz="0.00103"/>
		</inertial>
		<visual>
			<origin rpy="0.00000 1.57080 0.00000" xyz="0.00000 0.00000 -0.10650"/>
			<geometry>
				<box size="0.11000 0.02450 0.03400"/>
			</geometry>
			<material name="">
				<color rgba="0.00000 0.00000 0.00000 0.50000" />
			</material>
		</visual>
		<collision>
			<origin rpy="0.00000 1.57080 0.00000" xyz="0.00000 0.00000 -0.10650"/>
			<geometry>
				<box size="0.11000 0.02450 0.03400"/>
			</geometry>
		</collision>
	</link>
	<link name="RL_calf">
		<inertial>
			<origin rpy="0.00000 0.00000 0.00000" xyz="0.00548 -0.00097 -0.11500"/>
			<mass value="0.15400"/>
			<inertia ixx="0.00108" ixy="0.00000" ixz="0.00002" iyy="0.00110" iyz="0.00001" izz="0.00003"/>
		</inertial>
		<visual>
			<origin rpy="0.00000 -0.20000 0.00000" xyz="0.01000 0.00000 -0.06000"/>
			<geometry>
				<cylinder length="0.12000" radius="0.01300"/>
			</geometry>
			<material name="">
				<color rgba="0.00000 0.00000 0.00000 0.50000" />
			</material>
		</visual>
		<collision>
			<origin rpy="0.00000 -0.20000 0.00000" xyz="0.01000 0.00000 -0.06000"/>
			<geometry>
				<cylinder length="0.12000" radius="0.01300"/>
			</geometry>
		</collision>
	</link>
	<link name="RL_calflower">
		<inertial>
			<origin rpy="0.00000 0.00000 0.00000" xyz="0.00000 0.00000 0.00000"/>
			<mass value="0.00100"/>
			<inertia ixx="0.00001" ixy="0.00000" ixz="0.00000" iyy="0.00001" iyz="0.00000" izz="0.00001"/>
		</inertial>
		<visual>
			<origin rpy="0.00000 0.00000 0.00000" xyz="0.00000 0.00000 0.00000"/>
			<geometry>
				<cylinder length="0.06500" radius="0.01100"/>
			</geometry>
			<material name="">
				<color rgba="0.00000 0.00000 0.00000 0.50000" />
			</material>
		</visual>
		<collision>
			<origin rpy="0.00000 0.00000 0.00000" xyz="0.00000 0.00000 0.00000"/>
			<geometry>
				<cylinder length="0.06500" radius="0.01100"/>
			</geometry>
		</collision>
	</link>
	<link name="RL_calflower1">
		<inertial>
			<origin rpy="0.00000 0.00000 0.00000" xyz="0.00000 0.00000 0.00000"/>
			<mass value="0.00100"/>
			<inertia ixx="0.00001" ixy="0.00000" ixz="0.00000" iyy="0.00001" iyz="0.00000" izz="0.00001"/>
		</inertial>
		<visual>
			<origin rpy="0.00000 0.00000 0.00000" xyz="0.00000 0.00000 0.00000"/>
			<geometry>
				<cylinder length="0.03000" radius="0.01550"/>
			</geometry>
			<material name="">
				<color rgba="0.00000 0.00000 0.00000 0.50000" />
			</material>
		</visual>
		<collision>
			<origin rpy="0.00000 0.00000 0.00000" xyz="0.00000 0.00000 0.00000"/>
			<geometry>
				<cylinder length="0.03000" radius="0.01550"/>
			</geometry>
		</collision>
	</link>
	<link name="RL_foot">
		<inertial>
			<origin rpy="0.00000 0.00000 0.00000" xyz="0.00000 0.00000 0.00000"/>
			<mass value="0.04000"/>
			<inertia ixx="0.00001" ixy="0.00000" ixz="0.00000" iyy="0.00001" iyz="0.00000" izz="0.00001"/>
		</inertial>
		<visual>
			<origin rpy="0.00000 0.00000 0.00000" xyz="-0.00200 0.00000 0.00000"/>
			<geometry>
				<sphere radius="0.02200"/>
			</geometry>
			<material name="">
				<color rgba="0.00000 0.00000 0.00000 0.50000" />
			</material>
		</visual>
		<collision>
			<origin rpy="0.00000 0.00000 0.00000" xyz="-0.00200 0.00000 0.00000"/>
			<geometry>
				<sphere radius="0.02200"/>
			</geometry>
		</collision>
	</link>
	<link name="RR_hip">
		<inertial>
			<origin rpy="0.00000 0.00000 0.00000" xyz="0.00540 -0.00194 -0.00011"/>
			<mass value="0.67800"/>
			<inertia ixx="0.00048" ixy="-0.00000" ixz="-0.00000" iyy="0.00088" iyz="0.00000" izz="0.00060"/>
		</inertial>
		<visual>
			<origin rpy="1.57080 0.00000 0.00000" xyz="0.00000 -0.08000 0.00000"/>
			<geometry>
				<cylinder length="0.04000" radius="0.04600"/>
			</geometry>
			<material name="">
				<color rgba="0.00000 0.00000 0.00000 0.50000" />
			</material>
		</visual>
		<collision>
			<origin rpy="1.57080 0.00000 0.00000" xyz="0.00000 -0.08000 0.00000"/>
			<geometry>
				<cylinder length="0.04000" radius="0.04600"/>
			</geometry>
		</collision>
	</link>
	<link name="RR_thigh">
		<inertial>
			<origin rpy="0.00000 0.00000 0.00000" xyz="-0.00374 0.02230 -0.03270"/>
			<mass value="1.15200"/>
			<inertia ixx="0.00584" ixy="-0.00009" ixz="-0.00029" iyy="0.00580" iyz="-0.00081" izz="0.00103"/>
		</inertial>
		<visual>
			<origin rpy="0.00000 1.57080 0.00000" xyz="0.00000 0.00000 -0.10650"/>
			<geometry>
				<box size="0.11000 0.02450 0.03400"/>
			</geometry>
			<material name="">
				<color rgba="0.00000 0.00000 0.00000 0.50000" />
			</material>
		</visual>
		<collision>
			<origin rpy="0.00000 1.57080 0.00000" xyz="0.00000 0.00000 -0.10650"/>
			<geometry>
				<box size="0.11000 0.02450 0.03400"/>
			</geometry>
		</collision>
	</link>
	<link name="RR_calf">
		<inertial>
			<origin rpy="0.00000 0.00000 0.00000" xyz="0.00548 0.00097 -0.11500"/>
			<mass value="0.15400"/>
			<inertia ixx="0.00108" ixy="-0.00000" ixz="0.00002" iyy="0.00110" iyz="-0.00001" izz="0.00003"/>
		</inertial>
		<visual>
			<origin rpy="0.00000 -0.20000 0.00000" xyz="0.01000 0.00000 -0.06000"/>
			<geometry>
				<cylinder length="0.12000" radius="0.01300"/>
			</geometry>
			<material name="">
				<color rgba="0.00000 0.00000 0.00000 0.50000" />
			</material>
		</visual>
		<collision>
			<origin rpy="0.00000 -0.20000 0.00000" xyz="0.01000 0.00000 -0.06000"/>
			<geometry>
				<cylinder length="0.12000" radius="0.01300"/>
			</geometry>
		</collision>
	</link>
	<link name="RR_calflower">
		<inertial>
			<origin rpy="0.00000 0.00000 0.00000" xyz="0.00000 0.00000 0.00000"/>
			<mass value="0.00100"/>
			<inertia ixx="0.00001" ixy="0.00000" ixz="0.00000" iyy="0.00001" iyz="0.00000" izz="0.00001"/>
		</inertial>
		<visual>
			<origin rpy="0.00000 0.00000 0.00000" xyz="0.00000 0.00000 0.00000"/>
			<geometry>
				<cylinder length="0.06500" radius="0.01100"/>
			</geometry>
			<material name="">
				<color rgba="0.00000 0.00000 0.00000 0.50000" />
			</material>
		</visual>
		<collision>
			<origin rpy="0.00000 0.00000 0.00000" xyz="0.00000 0.00000 0.00000"/>
			<geometry>
				<cylinder length="0.06500" radius="0.01100"/>
			</geometry>
		</collision>
	</link>
	<link name="RR_calflower1">
		<inertial>
			<origin rpy="0.00000 0.00000 0.00000" xyz="0.00000 0.00000 0.00000"/>
			<mass value="0.00100"/>
			<inertia ixx="0.00001" ixy="0.00000" ixz="0.00000" iyy="0.00001" iyz="0.00000" izz="0.00001"/>
		</inertial>
		<visual>
			<origin rpy="0.00000 0.00000 0.00000" xyz="0.00000 0.00000 0.00000"/>
			<geometry>
				<cylinder length="0.03000" radius="0.01550"/>
			</geometry>
			<material name="">
				<color rgba="0.00000 0.00000 0.00000 0.50000" />
			</material>
		</visual>
		<collision>
			<origin rpy="0.00000 0.00000 0.00000" xyz="0.00000 0.00000 0.00000"/>
			<geometry>
				<cylinder length="0.03000" radius="0.01550"/>
			</geometry>
		</collision>
	</link>
	<link name="RR_foot">
		<inertial>
			<origin rpy="0.00000 0.00000 0.00000" xyz="0.00000 0.00000 0.00000"/>
			<mass value="0.04000"/>
			<inertia ixx="0.00001" ixy="0.00000" ixz="0.00000" iyy="0.00001" iyz="0.00000" izz="0.00001"/>
		</inertial>
		<visual>
			<origin rpy="0.00000 0.00000 0.00000" xyz="-0.00200 0.00000 0.00000"/>
			<geometry>
				<sphere radius="0.02200"/>
			</geometry>
			<material name="">
				<color rgba="0.00000 0.00000 0.00000 0.50000" />
			</material>
		</visual>
		<collision>
			<origin rpy="0.00000 0.00000 0.00000" xyz="-0.00200 0.00000 0.00000"/>
			<geometry>
				<sphere radius="0.02200"/>
			</geometry>
		</collision>
	</link>
	<link name="imu">
		<inertial>
			<origin rpy="0.00000 0.00000 0.00000" xyz="0.00000 0.00000 0.00000"/>
			<mass value="0.00000"/>
			<inertia ixx="0.00000" ixy="0.00000" ixz="0.00000" iyy="0.00000" iyz="0.00000" izz="0.00000"/>
		</inertial>
	</link>
	<link name="radar">
		<inertial>
			<origin rpy="0.00000 0.00000 0.00000" xyz="0.00000 0.00000 0.00000"/>
			<mass value="0.00000"/>
			<inertia ixx="0.00000" ixy="0.00000" ixz="0.00000" iyy="0.00000" iyz="0.00000" izz="0.00000"/>
		</inertial>
	</link>
	<joint name="Head_upper_joint" type="fixed">
		<parent link="base"/>
		<child link="Head_upper"/>
		<dynamics damping="0.00000" friction="0.00000"/>
		<origin rpy="0.00000 0.00000 0.00000" xyz="0.28500 0.00000 0.01000"/>
		<axis xyz="0.00000 0.00000 0.00000"/>
	</joint>
	<joint name="Head_lower_joint" type="fixed">
		<parent link="Head_upper"/>
		<child link="Head_lower"/>
		<dynamics damping="0.00000" friction="0.00000"/>
		<origin rpy="0.00000 0.00000 0.00000" xyz="0.00800 0.00000 -0.07000"/>
		<axis xyz="0.00000 0.00000 0.00000"/>
	</joint>
	<joint name="FL_hip_joint" type="revolute">
		<parent link="base"/>
		<child link="FL_hip"/>
		<limit effort="23.70000" lower="-1.04720" upper="1.04720" velocity="30.10000"/>
		<dynamics damping="0.00000" friction="0.00000"/>
		<origin rpy="0.00000 0.00000 0.00000" xyz="0.19340 0.04650 0.00000"/>
		<axis xyz="1.00000 0.00000 0.00000"/>
	</joint>
	<joint name="FL_thigh_joint" type="revolute">
		<parent link="FL_hip"/>
		<child link="FL_thigh"/>
		<limit effort="23.70000" lower="-1.57080" upper="3.49070" velocity="30.10000"/>
		<dynamics damping="0.00000" friction="0.00000"/>
		<origin rpy="0.00000 0.00000 0.00000" xyz="0.00000 0.09550 0.00000"/>
		<axis xyz="0.00000 1.00000 0.00000"/>
	</joint>
	<joint name="FL_calf_joint" type="revolute">
		<parent link="FL_thigh"/>
		<child link="FL_calf"/>
		<limit effort="35.55000" lower="-2.72270" upper="-0.83776" velocity="20.07000"/>
		<dynamics damping="0.00000" friction="0.00000"/>
		<origin rpy="0.00000 0.00000 0.00000" xyz="0.00000 0.00000 -0.21300"/>
		<axis xyz="0.00000 1.00000 0.00000"/>
	</joint>
	<joint name="FL_calflower_joint" type="fixed">
		<parent link="FL_calf"/>
		<child link="FL_calflower"/>
		<dynamics damping="0.00000" friction="0.00000"/>
		<origin rpy="0.00000 0.05000 0.00000" xyz="0.02000 0.00000 -0.14800"/>
		<axis xyz="0.00000 0.00000 0.00000"/>
	</joint>
	<joint name="FL_calflower1_joint" type="fixed">
		<parent link="FL_calflower"/>
		<child link="FL_calflower1"/>
		<dynamics damping="0.00000" friction="0.00000"/>
		<origin rpy="0.00000 0.48000 0.00000" xyz="-0.01000 0.00000 -0.04000"/>
		<axis xyz="0.00000 0.00000 0.00000"/>
	</joint>
	<joint name="FL_foot_joint" type="fixed">
		<parent link="FL_calf"/>
		<child link="FL_foot"/>
		<dynamics damping="0.00000" friction="0.00000"/>
		<origin rpy="0.00000 0.00000 0.00000" xyz="0.00000 0.00000 -0.21300"/>
		<axis xyz="0.00000 0.00000 0.00000"/>
	</joint>
	<joint name="FR_hip_joint" type="revolute">
		<parent link="base"/>
		<child link="FR_hip"/>
		<limit effort="23.70000" lower="-1.04720" upper="1.04720" velocity="30.10000"/>
		<dynamics damping="0.00000" friction="0.00000"/>
		<origin rpy="0.00000 0.00000 0.00000" xyz="0.19340 -0.04650 0.00000"/>
		<axis xyz="1.00000 0.00000 0.00000"/>
	</joint>
	<joint name="FR_thigh_joint" type="revolute">
		<parent link="FR_hip"/>
		<child link="FR_thigh"/>
		<limit effort="23.70000" lower="-1.57080" upper="3.49070" velocity="30.10000"/>
		<dynamics damping="0.00000" friction="0.00000"/>
		<origin rpy="0.00000 0.00000 0.00000" xyz="0.00000 -0.09550 0.00000"/>
		<axis xyz="0.00000 1.00000 0.00000"/>
	</joint>
	<joint name="FR_calf_joint" type="revolute">
		<parent link="FR_thigh"/>
		<child link="FR_calf"/>
		<limit effort="35.55000" lower="-2.72270" upper="-0.83776" velocity="20.07000"/>
		<dynamics damping="0.00000" friction="0.00000"/>
		<origin rpy="0.00000 0.00000 0.00000" xyz="0.00000 0.00000 -0.21300"/>
		<axis xyz="0.00000 1.00000 0.00000"/>
	</joint>
	<joint name="FR_calflower_joint" type="fixed">
		<parent link="FR_calf"/>
		<child link="FR_calflower"/>
		<dynamics damping="0.00000" friction="0.00000"/>
		<origin rpy="0.00000 0.05000 0.00000" xyz="0.02000 0.00000 -0.14800"/>
		<axis xyz="0.00000 0.00000 0.00000"/>
	</joint>
	<joint name="FR_calflower1_joint" type="fixed">
		<parent link="FR_calflower"/>
		<child link="FR_calflower1"/>
		<dynamics damping="0.00000" friction="0.00000"/>
		<origin rpy="0.00000 0.48000 0.00000" xyz="-0.01000 0.00000 -0.04000"/>
		<axis xyz="0.00000 0.00000 0.00000"/>
	</joint>
	<joint name="FR_foot_joint" type="fixed">
		<parent link="FR_calf"/>
		<child link="FR_foot"/>
		<dynamics damping="0.00000" friction="0.00000"/>
		<origin rpy="0.00000 0.00000 0.00000" xyz="0.00000 0.00000 -0.21300"/>
		<axis xyz="0.00000 0.00000 0.00000"/>
	</joint>
	<joint name="RL_hip_joint" type="revolute">
		<parent link="base"/>
		<child link="RL_hip"/>
		<limit effort="23.70000" lower="-1.04720" upper="1.04720" velocity="30.10000"/>
		<dynamics damping="0.00000" friction="0.00000"/>
		<origin rpy="0.00000 0.00000 0.00000" xyz="-0.19340 0.04650 0.00000"/>
		<axis xyz="1.00000 0.00000 0.00000"/>
	</joint>
	<joint name="RL_thigh_joint" type="revolute">
		<parent link="RL_hip"/>
		<child link="RL_thigh"/>
		<limit effort="23.70000" lower="-0.52360" upper="4.53790" velocity="30.10000"/>
		<dynamics damping="0.00000" friction="0.00000"/>
		<origin rpy="0.00000 0.00000 0.00000" xyz="0.00000 0.09550 0.00000"/>
		<axis xyz="0.00000 1.00000 0.00000"/>
	</joint>
	<joint name="RL_calf_joint" type="revolute">
		<parent link="RL_thigh"/>
		<child link="RL_calf"/>
		<limit effort="35.55000" lower="-2.72270" upper="-0.83776" velocity="20.07000"/>
		<dynamics damping="0.00000" friction="0.00000"/>
		<origin rpy="0.00000 0.00000 0.00000" xyz="0.00000 0.00000 -0.21300"/>
		<axis xyz="0.00000 1.00000 0.00000"/>
	</joint>
	<joint name="RL_calflower_joint" type="fixed">
		<parent link="RL_calf"/>
		<child link="RL_calflower"/>
		<dynamics damping="0.00000" friction="0.00000"/>
		<origin rpy="0.00000 0.05000 0.00000" xyz="0.02000 0.00000 -0.14800"/>
		<axis xyz="0.00000 0.00000 0.00000"/>
	</joint>
	<joint name="RL_calflower1_joint" type="fixed">
		<parent link="RL_calflower"/>
		<child link="RL_calflower1"/>
		<dynamics damping="0.00000" friction="0.00000"/>
		<origin rpy="0.00000 0.48000 0.00000" xyz="-0.01000 0.00000 -0.04000"/>
		<axis xyz="0.00000 0.00000 0.00000"/>
	</joint>
	<joint name="RL_foot_joint" type="fixed">
		<parent link="RL_calf"/>
		<child link="RL_foot"/>
		<dynamics damping="0.00000" friction="0.00000"/>
		<origin rpy="0.00000 0.00000 0.00000" xyz="0.00000 0.00000 -0.21300"/>
		<axis xyz="0.00000 0.00000 0.00000"/>
	</joint>
	<joint name="RR_hip_joint" type="revolute">
		<parent link="base"/>
		<child link="RR_hip"/>
		<limit effort="23.70000" lower="-1.04720" upper="1.04720" velocity="30.10000"/>
		<dynamics damping="0.00000" friction="0.00000"/>
		<origin rpy="0.00000 0.00000 0.00000" xyz="-0.19340 -0.04650 0.00000"/>
		<axis xyz="1.00000 0.00000 0.00000"/>
	</joint>
	<joint name="RR_thigh_joint" type="revolute">
		<parent link="RR_hip"/>
		<child link="RR_thigh"/>
		<limit effort="23.70000" lower="-0.52360" upper="4.53790" velocity="30.10000"/>
		<dynamics damping="0.00000" friction="0.00000"/>
		<origin rpy="0.00000 0.00000 0.00000" xyz="0.00000 -0.09550 0.00000"/>
		<axis xyz="0.00000 1.00000 0.00000"/>
	</joint>
	<joint name="RR_calf_joint" type="revolute">
		<parent link="RR_thigh"/>
		<child link="RR_calf"/>
		<limit effort="35.55000" lower="-2.72270" upper="-0.83776" velocity="20.07000"/>
		<dynamics damping="0.00000" friction="0.00000"/>
		<origin rpy="0.00000 0.00000 0.00000" xyz="0.00000 0.00000 -0.21300"/>
		<axis xyz="0.00000 1.00000 0.00000"/>
	</joint>
	<joint name="RR_calflower_joint" type="fixed">
		<parent link="RR_calf"/>
		<child link="RR_calflower"/>
		<dynamics damping="0.00000" friction="0.00000"/>
		<origin rpy="0.00000 0.05000 0.00000" xyz="0.02000 0.00000 -0.14800"/>
		<axis xyz="0.00000 0.00000 0.00000"/>
	</joint>
	<joint name="RR_calflower1_joint" type="fixed">
		<parent link="RR_calflower"/>
		<child link="RR_calflower1"/>
		<dynamics damping="0.00000" friction="0.00000"/>
		<origin rpy="0.00000 0.48000 0.00000" xyz="-0.01000 0.00000 -0.04000"/>
		<axis xyz="0.00000 0.00000 0.00000"/>
	</joint>
	<joint name="RR_foot_joint" type="fixed">
		<parent link="RR_calf"/>
		<child link="RR_foot"/>
		<dynamics damping="0.00000" friction="0.00000"/>
		<origin rpy="0.00000 0.00000 0.00000" xyz="0.00000 0.00000 -0.21300"/>
		<axis xyz="0.00000 0.00000 0.00000"/>
	</joint>
	<joint name="imu_joint" type="fixed">
		<parent link="base"/>
		<child link="imu"/>
		<dynamics damping="0.00000" friction="0.00000"/>
		<origin rpy="0.00000 0.00000 0.00000" xyz="-0.02557 0.00000 0.04232"/>
		<axis xyz="0.00000 0.00000 0.00000"/>
	</joint>
	<joint name="radar_joint" type="fixed">
		<parent link="base"/>
		<child link="radar"/>
		<dynamics damping="0.00000" friction="0.00000"/>
		<origin rpy="0.00000 2.87820 0.00000" xyz="0.28945 0.00000 -0.04682"/>
		<axis xyz="0.00000 0.00000 0.00000"/>
	</joint>
</robot>
