<?xml version="0.0" ?>
<robot name="cheetah">
	<link name="body">
		<inertial>
			<origin rpy="0.00000 0.00000 0.00000" xyz="0.00000 0.00000 0.00000"/>
			<mass value="3.30000"/>
			<inertia ixx="0.01125" ixy="0.00000" ixz="0.00000" iyy="0.03620" iyz="0.00000" izz="0.04267"/>
		</inertial>
		<visual>
			<origin rpy="0.00000 0.00000 0.00000" xyz="0.00000 0.00000 0.00000"/>
			<geometry>
				<mesh filename="meshes/mini_body.obj" scale="1.00000 1.00000 1.00000"/>
			</geometry>
			<material name="">
				<color rgba="0.00000 0.00000 0.00000 0.50000" />
			</material>
		</visual>
		<collision>
			<origin rpy="0.00000 0.00000 0.00000" xyz="0.00000 0.00000 0.00000"/>
			<geometry>
				<mesh filename="meshes/mini_body.obj" scale="1.00000 1.00000 1.00000"/>
			</geometry>
		</collision>
	</link>
	<link name="abduct_fr">
		<inertial>
			<origin rpy="0.00000 0.00000 0.00000" xyz="0.00000 0.03600 0.00000"/>
			<mass value="0.54000"/>
			<inertia ixx="0.00038" ixy="0.00006" ixz="0.00000" iyy="0.00056" iyz="0.00000" izz="0.00044"/>
		</inertial>
		<visual>
			<origin rpy="3.14159 0.00000 1.57080" xyz="-0.05500 0.00000 0.00000"/>
			<geometry>
				<mesh filename="meshes/mini_abad.obj" scale="1.00000 1.00000 1.00000"/>
			</geometry>
			<material name="">
				<color rgba="0.00000 0.00000 0.00000 0.50000" />
			</material>
		</visual>
		<collision>
			<origin rpy="3.14159 0.00000 1.57080" xyz="-0.05500 0.00000 0.00000"/>
			<geometry>
				<mesh filename="meshes/mini_abad.obj" scale="1.00000 1.00000 1.00000"/>
			</geometry>
		</collision>
	</link>
	<link name="thigh_fr">
		<inertial>
			<origin rpy="0.00000 0.00000 0.00000" xyz="0.00000 0.01600 -0.02000"/>
			<mass value="0.63400"/>
			<inertia ixx="0.00198" ixy="0.00024" ixz="0.00001" iyy="0.00210" iyz="0.00000" izz="0.00041"/>
		</inertial>
		<visual>
			<origin rpy="0.00000 -1.57080 0.00000" xyz="0.00000 0.00000 0.00000"/>
			<geometry>
				<mesh filename="meshes/mini_upper_link.obj" scale="1.00000 1.00000 1.00000"/>
			</geometry>
			<material name="">
				<color rgba="0.00000 0.00000 0.00000 0.50000" />
			</material>
		</visual>
		<collision>
			<origin rpy="0.00000 -1.57080 0.00000" xyz="0.00000 0.00000 0.00000"/>
			<geometry>
				<mesh filename="meshes/mini_upper_link.obj" scale="1.00000 1.00000 1.00000"/>
			</geometry>
		</collision>
	</link>
	<link name="shank_fr">
		<inertial>
			<origin rpy="0.00000 0.00000 0.00000" xyz="0.00000 0.00000 -0.20900"/>
			<mass value="0.06400"/>
			<inertia ixx="0.00024" ixy="0.00000" ixz="0.00000" iyy="0.00025" iyz="0.00000" izz="0.00001"/>
		</inertial>
		<visual>
			<origin rpy="0.00000 3.14159 0.00000" xyz="0.00000 0.00000 0.00000"/>
			<geometry>
				<mesh filename="meshes/mini_lower_link.obj" scale="1.00000 1.00000 1.00000"/>
			</geometry>
			<material name="">
				<color rgba="0.00000 0.00000 0.00000 0.50000" />
			</material>
		</visual>
		<collision>
			<origin rpy="0.00000 3.14159 0.00000" xyz="0.00000 0.00000 0.00000"/>
			<geometry>
				<mesh filename="meshes/mini_lower_link.obj" scale="1.00000 1.00000 1.00000"/>
			</geometry>
		</collision>
	</link>
	<link name="toe_fr">
		<inertial>
			<origin rpy="0.00000 0.00000 0.00000" xyz="0.00000 0.00000 0.00000"/>
			<mass value="0.15000"/>
			<inertia ixx="0.00003" ixy="0.00000" ixz="0.00000" iyy="0.00003" iyz="0.00000" izz="0.00003"/>
		</inertial>
		<visual>
			<origin rpy="0.00000 0.00000 0.00000" xyz="0.00000 0.00000 0.00000"/>
			<geometry>
				<sphere radius="0.01500"/>
			</geometry>
			<material name="">
				<color rgba="0.00000 0.00000 0.00000 0.50000" />
			</material>
		</visual>
		<collision>
			<origin rpy="0.00000 0.00000 0.00000" xyz="0.00000 0.00000 0.00000"/>
			<geometry>
				<sphere radius="0.01500"/>
			</geometry>
		</collision>
	</link>
	<link name="abduct_fl">
		<inertial>
			<origin rpy="0.00000 0.00000 0.00000" xyz="0.00000 0.03600 0.00000"/>
			<mass value="0.54000"/>
			<inertia ixx="0.00038" ixy="0.00006" ixz="0.00000" iyy="0.00056" iyz="0.00000" izz="0.00044"/>
		</inertial>
		<visual>
			<origin rpy="0.00000 0.00000 -1.57080" xyz="-0.05500 0.00000 0.00000"/>
			<geometry>
				<mesh filename="meshes/mini_abad.obj" scale="1.00000 1.00000 1.00000"/>
			</geometry>
			<material name="">
				<color rgba="0.00000 0.00000 0.00000 0.50000" />
			</material>
		</visual>
		<collision>
			<origin rpy="0.00000 0.00000 -1.57080" xyz="-0.05500 0.00000 0.00000"/>
			<geometry>
				<mesh filename="meshes/mini_abad.obj" scale="1.00000 1.00000 1.00000"/>
			</geometry>
		</collision>
	</link>
	<link name="thigh_fl">
		<inertial>
			<origin rpy="0.00000 0.00000 0.00000" xyz="0.00000 0.01600 -0.02000"/>
			<mass value="0.63400"/>
			<inertia ixx="0.00198" ixy="0.00024" ixz="0.00001" iyy="0.00210" iyz="0.00000" izz="0.00041"/>
		</inertial>
		<visual>
			<origin rpy="0.00000 -1.57080 0.00000" xyz="0.00000 0.00000 0.00000"/>
			<geometry>
				<mesh filename="meshes/mini_upper_link.obj" scale="1.00000 1.00000 1.00000"/>
			</geometry>
			<material name="">
				<color rgba="0.00000 0.00000 0.00000 0.50000" />
			</material>
		</visual>
		<collision>
			<origin rpy="0.00000 -1.57080 0.00000" xyz="0.00000 0.00000 0.00000"/>
			<geometry>
				<mesh filename="meshes/mini_upper_link.obj" scale="1.00000 1.00000 1.00000"/>
			</geometry>
		</collision>
	</link>
	<link name="shank_fl">
		<inertial>
			<origin rpy="0.00000 0.00000 0.00000" xyz="0.00000 0.00000 -0.20900"/>
			<mass value="0.06400"/>
			<inertia ixx="0.00024" ixy="0.00000" ixz="0.00000" iyy="0.00025" iyz="0.00000" izz="0.00001"/>
		</inertial>
		<visual>
			<origin rpy="0.00000 3.14159 0.00000" xyz="0.00000 0.00000 0.00000"/>
			<geometry>
				<mesh filename="meshes/mini_lower_link.obj" scale="1.00000 1.00000 1.00000"/>
			</geometry>
			<material name="">
				<color rgba="0.00000 0.00000 0.00000 0.50000" />
			</material>
		</visual>
		<collision>
			<origin rpy="0.00000 3.14159 0.00000" xyz="0.00000 0.00000 0.00000"/>
			<geometry>
				<mesh filename="meshes/mini_lower_link.obj" scale="1.00000 1.00000 1.00000"/>
			</geometry>
		</collision>
	</link>
	<link name="toe_fl">
		<inertial>
			<origin rpy="0.00000 0.00000 0.00000" xyz="0.00000 0.00000 0.00000"/>
			<mass value="0.15000"/>
			<inertia ixx="0.00003" ixy="0.00000" ixz="0.00000" iyy="0.00003" iyz="0.00000" izz="0.00003"/>
		</inertial>
		<visual>
			<origin rpy="0.00000 0.00000 0.00000" xyz="0.00000 0.00000 0.00000"/>
			<geometry>
				<sphere radius="0.01500"/>
			</geometry>
			<material name="">
				<color rgba="0.00000 0.00000 0.00000 0.50000" />
			</material>
		</visual>
		<collision>
			<origin rpy="0.00000 0.00000 0.00000" xyz="0.00000 0.00000 0.00000"/>
			<geometry>
				<sphere radius="0.01500"/>
			</geometry>
		</collision>
	</link>
	<link name="abduct_hr">
		<inertial>
			<origin rpy="0.00000 0.00000 0.00000" xyz="0.00000 0.03600 0.00000"/>
			<mass value="0.54000"/>
			<inertia ixx="0.00038" ixy="0.00006" ixz="0.00000" iyy="0.00056" iyz="0.00000" izz="0.00044"/>
		</inertial>
		<visual>
			<origin rpy="0.00000 0.00000 1.57080" xyz="0.05500 0.00000 0.00000"/>
			<geometry>
				<mesh filename="meshes/mini_abad.obj" scale="1.00000 1.00000 1.00000"/>
			</geometry>
			<material name="">
				<color rgba="0.00000 0.00000 0.00000 0.50000" />
			</material>
		</visual>
		<collision>
			<origin rpy="0.00000 0.00000 1.57080" xyz="0.05500 0.00000 0.00000"/>
			<geometry>
				<mesh filename="meshes/mini_abad.obj" scale="1.00000 1.00000 1.00000"/>
			</geometry>
		</collision>
	</link>
	<link name="thigh_hr">
		<inertial>
			<origin rpy="0.00000 0.00000 0.00000" xyz="0.00000 0.01600 -0.02000"/>
			<mass value="0.63400"/>
			<inertia ixx="0.00198" ixy="0.00024" ixz="0.00001" iyy="0.00210" iyz="0.00000" izz="0.00041"/>
		</inertial>
		<visual>
			<origin rpy="0.00000 -1.57080 0.00000" xyz="0.00000 0.00000 0.00000"/>
			<geometry>
				<mesh filename="meshes/mini_upper_link.obj" scale="1.00000 1.00000 1.00000"/>
			</geometry>
			<material name="">
				<color rgba="0.00000 0.00000 0.00000 0.50000" />
			</material>
		</visual>
		<collision>
			<origin rpy="0.00000 -1.57080 0.00000" xyz="0.00000 0.00000 0.00000"/>
			<geometry>
				<mesh filename="meshes/mini_upper_link.obj" scale="1.00000 1.00000 1.00000"/>
			</geometry>
		</collision>
	</link>
	<link name="shank_hr">
		<inertial>
			<origin rpy="0.00000 0.00000 0.00000" xyz="0.00000 0.00000 -0.20900"/>
			<mass value="0.06400"/>
			<inertia ixx="0.00024" ixy="0.00000" ixz="0.00000" iyy="0.00025" iyz="0.00000" izz="0.00001"/>
		</inertial>
		<visual>
			<origin rpy="0.00000 3.14159 0.00000" xyz="0.00000 0.00000 0.00000"/>
			<geometry>
				<mesh filename="meshes/mini_lower_link.obj" scale="1.00000 1.00000 1.00000"/>
			</geometry>
			<material name="">
				<color rgba="0.00000 0.00000 0.00000 0.50000" />
			</material>
		</visual>
		<collision>
			<origin rpy="0.00000 3.14159 0.00000" xyz="0.00000 0.00000 0.00000"/>
			<geometry>
				<mesh filename="meshes/mini_lower_link.obj" scale="1.00000 1.00000 1.00000"/>
			</geometry>
		</collision>
	</link>
	<link name="toe_hr">
		<inertial>
			<origin rpy="0.00000 0.00000 0.00000" xyz="0.00000 0.00000 0.00000"/>
			<mass value="0.15000"/>
			<inertia ixx="0.00003" ixy="0.00000" ixz="0.00000" iyy="0.00003" iyz="0.00000" izz="0.00003"/>
		</inertial>
		<visual>
			<origin rpy="0.00000 0.00000 0.00000" xyz="0.00000 0.00000 0.00000"/>
			<geometry>
				<sphere radius="0.01500"/>
			</geometry>
			<material name="">
				<color rgba="0.00000 0.00000 0.00000 0.50000" />
			</material>
		</visual>
		<collision>
			<origin rpy="0.00000 0.00000 0.00000" xyz="0.00000 0.00000 0.00000"/>
			<geometry>
				<sphere radius="0.01500"/>
			</geometry>
		</collision>
	</link>
	<link name="abduct_hl">
		<inertial>
			<origin rpy="0.00000 0.00000 0.00000" xyz="0.00000 0.03600 0.00000"/>
			<mass value="0.54000"/>
			<inertia ixx="0.00038" ixy="0.00006" ixz="0.00000" iyy="0.00056" iyz="0.00000" izz="0.00044"/>
		</inertial>
		<visual>
			<origin rpy="3.14159 0.00000 -1.57080" xyz="0.05500 0.00000 0.00000"/>
			<geometry>
				<mesh filename="meshes/mini_abad.obj" scale="1.00000 1.00000 1.00000"/>
			</geometry>
			<material name="">
				<color rgba="0.00000 0.00000 0.00000 0.50000" />
			</material>
		</visual>
		<collision>
			<origin rpy="3.14159 0.00000 -1.57080" xyz="0.05500 0.00000 0.00000"/>
			<geometry>
				<mesh filename="meshes/mini_abad.obj" scale="1.00000 1.00000 1.00000"/>
			</geometry>
		</collision>
	</link>
	<link name="thigh_hl">
		<inertial>
			<origin rpy="0.00000 0.00000 0.00000" xyz="0.00000 0.01600 -0.02000"/>
			<mass value="0.63400"/>
			<inertia ixx="0.00198" ixy="0.00024" ixz="0.00001" iyy="0.00210" iyz="0.00000" izz="0.00041"/>
		</inertial>
		<visual>
			<origin rpy="0.00000 -1.57080 0.00000" xyz="0.00000 0.00000 0.00000"/>
			<geometry>
				<mesh filename="meshes/mini_upper_link.obj" scale="1.00000 1.00000 1.00000"/>
			</geometry>
			<material name="">
				<color rgba="0.00000 0.00000 0.00000 0.50000" />
			</material>
		</visual>
		<collision>
			<origin rpy="0.00000 -1.57080 0.00000" xyz="0.00000 0.00000 0.00000"/>
			<geometry>
				<mesh filename="meshes/mini_upper_link.obj" scale="1.00000 1.00000 1.00000"/>
			</geometry>
		</collision>
	</link>
	<link name="shank_hl">
		<inertial>
			<origin rpy="0.00000 0.00000 0.00000" xyz="0.00000 0.00000 -0.20900"/>
			<mass value="0.06400"/>
			<inertia ixx="0.00024" ixy="0.00000" ixz="0.00000" iyy="0.00025" iyz="0.00000" izz="0.00001"/>
		</inertial>
		<visual>
			<origin rpy="0.00000 3.14159 0.00000" xyz="0.00000 0.00000 0.00000"/>
			<geometry>
				<mesh filename="meshes/mini_lower_link.obj" scale="1.00000 1.00000 1.00000"/>
			</geometry>
			<material name="">
				<color rgba="0.00000 0.00000 0.00000 0.50000" />
			</material>
		</visual>
		<collision>
			<origin rpy="0.00000 3.14159 0.00000" xyz="0.00000 0.00000 0.00000"/>
			<geometry>
				<mesh filename="meshes/mini_lower_link.obj" scale="1.00000 1.00000 1.00000"/>
			</geometry>
		</collision>
	</link>
	<link name="toe_hl">
		<inertial>
			<origin rpy="0.00000 0.00000 0.00000" xyz="0.00000 0.00000 0.00000"/>
			<mass value="0.15000"/>
			<inertia ixx="0.00003" ixy="0.00000" ixz="0.00000" iyy="0.00003" iyz="0.00000" izz="0.00003"/>
		</inertial>
		<visual>
			<origin rpy="0.00000 0.00000 0.00000" xyz="0.00000 0.00000 0.00000"/>
			<geometry>
				<sphere radius="0.01500"/>
			</geometry>
			<material name="">
				<color rgba="0.00000 0.00000 0.00000 0.50000" />
			</material>
		</visual>
		<collision>
			<origin rpy="0.00000 0.00000 0.00000" xyz="0.00000 0.00000 0.00000"/>
			<geometry>
				<sphere radius="0.01500"/>
			</geometry>
		</collision>
	</link>
	<joint name="torso_to_abduct_fr_j" type="revolute">
		<parent link="body"/>
		<child link="abduct_fr"/>
		<limit effort="0.00000" lower="-3.14000" upper="3.14000" velocity="0.00000"/>
		<dynamics damping="0.00000" friction="0.00000"/>
		<origin rpy="0.00000 0.00000 0.00000" xyz="0.19000 -0.04900 0.00000"/>
		<axis xyz="1.00000 0.00000 0.00000"/>
	</joint>
	<joint name="abduct_fr_to_thigh_fr_j" type="revolute">
		<parent link="abduct_fr"/>
		<child link="thigh_fr"/>
		<limit effort="0.00000" lower="-3.14000" upper="3.14000" velocity="0.00000"/>
		<dynamics damping="0.00000" friction="0.00000"/>
		<origin rpy="0.00000 0.00000 0.00000" xyz="0.00000 -0.06200 0.00000"/>
		<axis xyz="0.00000 -1.00000 0.00000"/>
	</joint>
	<joint name="thigh_fr_to_knee_fr_j" type="revolute">
		<parent link="thigh_fr"/>
		<child link="shank_fr"/>
		<limit effort="0.00000" lower="-3.14000" upper="3.14000" velocity="0.00000"/>
		<dynamics damping="0.00000" friction="0.00000"/>
		<origin rpy="0.00000 0.00000 0.00000" xyz="0.00000 0.00000 -0.20900"/>
		<axis xyz="0.00000 -1.00000 0.00000"/>
	</joint>
	<joint name="toe_fr_joint" type="fixed">
		<parent link="shank_fr"/>
		<child link="toe_fr"/>
		<dynamics damping="0.00000" friction="0.00000"/>
		<origin rpy="1.00000 2.00000 3.00000" xyz="0.00000 0.00000 -0.18000"/>
		<axis xyz="1.00000 2.00000 3.00000"/>
	</joint>
	<joint name="torso_to_abduct_fl_j" type="revolute">
		<parent link="body"/>
		<child link="abduct_fl"/>
		<limit effort="0.00000" lower="-3.14000" upper="3.14000" velocity="0.00000"/>
		<dynamics damping="0.00000" friction="0.00000"/>
		<origin rpy="0.00000 0.00000 0.00000" xyz="0.19000 0.04900 0.00000"/>
		<axis xyz="1.00000 0.00000 0.00000"/>
	</joint>
	<joint name="abduct_fl_to_thigh_fl_j" type="revolute">
		<parent link="abduct_fl"/>
		<child link="thigh_fl"/>
		<limit effort="0.00000" lower="-3.14000" upper="3.14000" velocity="0.00000"/>
		<dynamics damping="0.00000" friction="0.00000"/>
		<origin rpy="0.00000 0.00000 0.00000" xyz="0.00000 0.06200 0.00000"/>
		<axis xyz="0.00000 -1.00000 0.00000"/>
	</joint>
	<joint name="thigh_fl_to_knee_fl_j" type="revolute">
		<parent link="thigh_fl"/>
		<child link="shank_fl"/>
		<limit effort="0.00000" lower="-3.14000" upper="3.14000" velocity="0.00000"/>
		<dynamics damping="0.00000" friction="0.00000"/>
		<origin rpy="0.00000 0.00000 0.00000" xyz="0.00000 0.00000 -0.20900"/>
		<axis xyz="0.00000 -1.00000 0.00000"/>
	</joint>
	<joint name="toe_fl_joint" type="fixed">
		<parent link="shank_fl"/>
		<child link="toe_fl"/>
		<dynamics damping="0.00000" friction="0.00000"/>
		<origin rpy="1.00000 2.00000 3.00000" xyz="0.00000 0.00000 -0.18000"/>
		<axis xyz="1.00000 2.00000 3.00000"/>
	</joint>
	<joint name="torso_to_abduct_hr_j" type="revolute">
		<parent link="body"/>
		<child link="abduct_hr"/>
		<limit effort="0.00000" lower="-3.14000" upper="3.14000" velocity="0.00000"/>
		<dynamics damping="0.00000" friction="0.00000"/>
		<origin rpy="0.00000 0.00000 0.00000" xyz="-0.19000 -0.04900 0.00000"/>
		<axis xyz="1.00000 0.00000 0.00000"/>
	</joint>
	<joint name="abduct_hr_to_thigh_hr_j" type="revolute">
		<parent link="abduct_hr"/>
		<child link="thigh_hr"/>
		<limit effort="0.00000" lower="-3.14000" upper="3.14000" velocity="0.00000"/>
		<dynamics damping="0.00000" friction="0.00000"/>
		<origin rpy="0.00000 0.00000 0.00000" xyz="0.00000 -0.06200 0.00000"/>
		<axis xyz="0.00000 -1.00000 0.00000"/>
	</joint>
	<joint name="thigh_hr_to_knee_hr_j" type="revolute">
		<parent link="thigh_hr"/>
		<child link="shank_hr"/>
		<limit effort="0.00000" lower="-3.14000" upper="3.14000" velocity="0.00000"/>
		<dynamics damping="0.00000" friction="0.00000"/>
		<origin rpy="0.00000 0.00000 0.00000" xyz="0.00000 0.00000 -0.20900"/>
		<axis xyz="0.00000 -1.00000 0.00000"/>
	</joint>
	<joint name="toe_hr_joint" type="fixed">
		<parent link="shank_hr"/>
		<child link="toe_hr"/>
		<dynamics damping="0.00000" friction="0.00000"/>
		<origin rpy="1.00000 2.00000 3.00000" xyz="0.00000 0.00000 -0.18000"/>
		<axis xyz="1.00000 2.00000 3.00000"/>
	</joint>
	<joint name="torso_to_abduct_hl_j" type="revolute">
		<parent link="body"/>
		<child link="abduct_hl"/>
		<limit effort="0.00000" lower="-3.14000" upper="3.14000" velocity="0.00000"/>
		<dynamics damping="0.00000" friction="0.00000"/>
		<origin rpy="0.00000 0.00000 0.00000" xyz="-0.19000 0.04900 0.00000"/>
		<axis xyz="1.00000 0.00000 0.00000"/>
	</joint>
	<joint name="abduct_hl_to_thigh_hl_j" type="revolute">
		<parent link="abduct_hl"/>
		<child link="thigh_hl"/>
		<limit effort="0.00000" lower="-3.14000" upper="3.14000" velocity="0.00000"/>
		<dynamics damping="0.00000" friction="0.00000"/>
		<origin rpy="0.00000 0.00000 0.00000" xyz="0.00000 0.06200 0.00000"/>
		<axis xyz="0.00000 -1.00000 0.00000"/>
	</joint>
	<joint name="thigh_hl_to_knee_hl_j" type="revolute">
		<parent link="thigh_hl"/>
		<child link="shank_hl"/>
		<limit effort="0.00000" lower="-3.14000" upper="3.14000" velocity="0.00000"/>
		<dynamics damping="0.00000" friction="0.00000"/>
		<origin rpy="0.00000 0.00000 0.00000" xyz="0.00000 0.00000 -0.20900"/>
		<axis xyz="0.00000 -1.00000 0.00000"/>
	</joint>
	<joint name="toe_hl_joint" type="fixed">
		<parent link="shank_hl"/>
		<child link="toe_hl"/>
		<dynamics damping="0.00000" friction="0.00000"/>
		<origin rpy="1.00000 2.00000 3.00000" xyz="0.00000 0.00000 -0.18000"/>
		<axis xyz="1.00000 2.00000 3.00000"/>
	</joint>
</robot>
