<?xml version="0.0" ?>
<robot name="max">
	<link name="body">
		<inertial>
			<origin rpy="0.00000 0.00000 0.00000" xyz="-0.00458 0.00307 0.00948"/>
			<mass value="5.76855"/>
			<inertia ixx="0.04783" ixy="0.00056" ixz="0.00015" iyy="0.10578" iyz="0.00054" izz="0.12101"/>
		</inertial>
		<visual>
			<origin rpy="0.00000 0.00000 0.00000" xyz="0.00000 0.00000 0.00000"/>
			<geometry>
				<box size="0.28300 0.20500 0.11000"/>
			</geometry>
			<material name="">
				<color rgba="0.00000 0.00000 0.00000 0.50000" />
			</material>
		</visual>
		<collision>
			<origin rpy="0.00000 0.00000 0.00000" xyz="0.00000 0.00000 0.00000"/>
			<geometry>
				<box size="0.28300 0.20500 0.11000"/>
			</geometry>
		</collision>
	</link>
	<link name="link_FR1">
		<inertial>
			<origin rpy="0.00000 0.00000 0.00000" xyz="-0.00287 0.00035 -0.00047"/>
			<mass value="0.60318"/>
			<inertia ixx="0.00037" ixy="-0.00000" ixz="-0.00000" iyy="0.00065" iyz="0.00001" izz="0.00042"/>
		</inertial>
		<visual>
			<origin rpy="1.57080 0.00000 0.00000" xyz="0.00000 0.00000 0.00000"/>
			<geometry>
				<cylinder length="0.02550" radius="0.04700"/>
			</geometry>
			<material name="">
				<color rgba="0.00000 0.00000 0.00000 0.50000" />
			</material>
		</visual>
		<collision>
			<origin rpy="1.57080 0.00000 0.00000" xyz="0.00000 0.00000 0.00000"/>
			<geometry>
				<cylinder length="0.02550" radius="0.04700"/>
			</geometry>
		</collision>
	</link>
	<link name="link_FR2">
		<inertial>
			<origin rpy="0.00000 0.00000 0.00000" xyz="-0.00070 0.02582 -0.02735"/>
			<mass value="0.87783"/>
			<inertia ixx="0.00363" ixy="-0.00000" ixz="0.00002" iyy="0.00370" iyz="0.00052" izz="0.00075"/>
		</inertial>
		<visual>
			<origin rpy="0.00000 1.57080 0.00000" xyz="0.00000 0.00000 -0.12000"/>
			<geometry>
				<box size="0.24000 0.02500 0.03500"/>
			</geometry>
			<material name="">
				<color rgba="0.00000 0.00000 0.00000 0.50000" />
			</material>
		</visual>
		<visual>
			<origin rpy="1.57080 0.00000 0.00000" xyz="0.00000 0.00000 0.00000"/>
			<geometry>
				<cylinder length="0.02500" radius="0.02300"/>
			</geometry>
			<material name="">
				<color rgba="0.00000 0.00000 0.00000 0.50000" />
			</material>
		</visual>
		<visual>
			<origin rpy="1.57080 0.00000 0.00000" xyz="0.00000 0.03000 0.00000"/>
			<geometry>
				<cylinder length="0.02500" radius="0.04700"/>
			</geometry>
			<material name="">
				<color rgba="0.00000 0.00000 0.00000 0.50000" />
			</material>
		</visual>
		<collision>
			<origin rpy="0.00000 1.57080 0.00000" xyz="0.00000 0.00000 -0.12000"/>
			<geometry>
				<box size="0.24000 0.02500 0.03500"/>
			</geometry>
		</collision>
		<collision>
			<origin rpy="1.57080 0.00000 0.00000" xyz="0.00000 0.00000 0.00000"/>
			<geometry>
				<cylinder length="0.02500" radius="0.02300"/>
			</geometry>
		</collision>
		<collision>
			<origin rpy="1.57080 0.00000 0.00000" xyz="0.00000 0.03000 0.00000"/>
			<geometry>
				<cylinder length="0.02500" radius="0.04700"/>
			</geometry>
		</collision>
	</link>
	<link name="link_FR3">
		<inertial>
			<origin rpy="0.00000 0.00000 0.00000" xyz="0.00155 0.00000 -0.12442"/>
			<mass value="0.16888"/>
			<inertia ixx="0.00152" ixy="0.00000" ixz="0.00007" iyy="0.00153" iyz="-0.00000" izz="0.00003"/>
		</inertial>
		<visual>
			<origin rpy="0.00000 1.57080 0.00000" xyz="0.00000 0.00000 -0.15120"/>
			<geometry>
				<box size="0.34560 0.02000 0.01800"/>
			</geometry>
			<material name="">
				<color rgba="0.00000 0.00000 0.00000 0.50000" />
			</material>
		</visual>
		<collision>
			<origin rpy="0.00000 1.57080 0.00000" xyz="0.00000 0.00000 -0.15120"/>
			<geometry>
				<box size="0.34560 0.02000 0.01800"/>
			</geometry>
		</collision>
	</link>
	<link name="link_FR4">
		<inertial>
			<origin rpy="0.00000 0.00000 0.00000" xyz="0.00000 0.00000 0.00000"/>
			<mass value="0.00000"/>
			<inertia ixx="0.00000" ixy="0.00000" ixz="0.00000" iyy="0.00000" iyz="0.00000" izz="0.00000"/>
		</inertial>
		<visual>
			<origin rpy="0.00000 0.00000 0.00000" xyz="0.00000 0.00000 0.00000"/>
			<geometry>
				<sphere radius="0.02500"/>
			</geometry>
			<material name="">
				<color rgba="0.00000 0.00000 0.00000 0.50000" />
			</material>
		</visual>
		<collision>
			<origin rpy="0.00000 0.00000 0.00000" xyz="0.00000 0.00000 0.00000"/>
			<geometry>
				<sphere radius="0.02500"/>
			</geometry>
		</collision>
	</link>
	<link name="link_FRW">
		<inertial>
			<origin rpy="0.00000 0.00000 0.00000" xyz="0.00000 0.00000 0.00000"/>
			<mass value="0.06293"/>
			<inertia ixx="0.00002" ixy="0.00000" ixz="0.00000" iyy="0.00003" iyz="0.00000" izz="0.00002"/>
		</inertial>
		<visual>
			<origin rpy="1.57080 0.00000 0.00000" xyz="0.00000 0.00000 0.00000"/>
			<geometry>
				<cylinder length="0.01200" radius="0.02800"/>
			</geometry>
			<material name="">
				<color rgba="0.00000 0.00000 0.00000 0.50000" />
			</material>
		</visual>
		<collision>
			<origin rpy="1.57080 0.00000 0.00000" xyz="0.00000 0.00000 0.00000"/>
			<geometry>
				<cylinder length="0.01200" radius="0.02800"/>
			</geometry>
		</collision>
	</link>
	<link name="link_FL1">
		<inertial>
			<origin rpy="0.00000 0.00000 0.00000" xyz="-0.00287 -0.00035 -0.00047"/>
			<mass value="0.60318"/>
			<inertia ixx="0.00037" ixy="0.00000" ixz="-0.00000" iyy="0.00065" iyz="-0.00001" izz="0.00042"/>
		</inertial>
		<visual>
			<origin rpy="1.57080 0.00000 0.00000" xyz="0.00000 0.00000 0.00000"/>
			<geometry>
				<cylinder length="0.02550" radius="0.04700"/>
			</geometry>
			<material name="">
				<color rgba="0.00000 0.00000 0.00000 0.50000" />
			</material>
		</visual>
		<collision>
			<origin rpy="1.57080 0.00000 0.00000" xyz="0.00000 0.00000 0.00000"/>
			<geometry>
				<cylinder length="0.02550" radius="0.04700"/>
			</geometry>
		</collision>
	</link>
	<link name="link_FL2">
		<inertial>
			<origin rpy="0.00000 0.00000 0.00000" xyz="-0.00070 -0.02582 -0.02735"/>
			<mass value="0.87783"/>
			<inertia ixx="0.00363" ixy="0.00000" ixz="0.00002" iyy="0.00370" iyz="-0.00052" izz="0.00075"/>
		</inertial>
		<visual>
			<origin rpy="0.00000 1.57080 0.00000" xyz="0.00000 0.00000 -0.12000"/>
			<geometry>
				<box size="0.24000 0.02500 0.03500"/>
			</geometry>
			<material name="">
				<color rgba="0.00000 0.00000 0.00000 0.50000" />
			</material>
		</visual>
		<visual>
			<origin rpy="1.57080 0.00000 0.00000" xyz="0.00000 0.00000 0.00000"/>
			<geometry>
				<cylinder length="0.02500" radius="0.02300"/>
			</geometry>
			<material name="">
				<color rgba="0.00000 0.00000 0.00000 0.50000" />
			</material>
		</visual>
		<visual>
			<origin rpy="1.57080 0.00000 0.00000" xyz="0.00000 -0.03000 0.00000"/>
			<geometry>
				<cylinder length="0.02500" radius="0.04700"/>
			</geometry>
			<material name="">
				<color rgba="0.00000 0.00000 0.00000 0.50000" />
			</material>
		</visual>
		<collision>
			<origin rpy="0.00000 1.57080 0.00000" xyz="0.00000 0.00000 -0.12000"/>
			<geometry>
				<box size="0.24000 0.02500 0.03500"/>
			</geometry>
		</collision>
		<collision>
			<origin rpy="1.57080 0.00000 0.00000" xyz="0.00000 0.00000 0.00000"/>
			<geometry>
				<cylinder length="0.02500" radius="0.02300"/>
			</geometry>
		</collision>
		<collision>
			<origin rpy="1.57080 0.00000 0.00000" xyz="0.00000 -0.03000 0.00000"/>
			<geometry>
				<cylinder length="0.02500" radius="0.04700"/>
			</geometry>
		</collision>
	</link>
	<link name="link_FL3">
		<inertial>
			<origin rpy="0.00000 0.00000 0.00000" xyz="0.00155 0.00000 -0.12442"/>
			<mass value="0.16888"/>
			<inertia ixx="0.00152" ixy="0.00000" ixz="0.00007" iyy="0.00153" iyz="-0.00000" izz="0.00003"/>
		</inertial>
		<visual>
			<origin rpy="0.00000 1.57080 0.00000" xyz="0.00000 0.00000 -0.17280"/>
			<geometry>
				<box size="0.34560 0.02000 0.01800"/>
			</geometry>
			<material name="">
				<color rgba="0.00000 0.00000 0.00000 0.50000" />
			</material>
		</visual>
		<collision>
			<origin rpy="0.00000 1.57080 0.00000" xyz="0.00000 0.00000 -0.17280"/>
			<geometry>
				<box size="0.34560 0.02000 0.01800"/>
			</geometry>
		</collision>
	</link>
	<link name="link_FL4">
		<inertial>
			<origin rpy="0.00000 0.00000 0.00000" xyz="0.00000 0.00000 0.00000"/>
			<mass value="0.00000"/>
			<inertia ixx="0.00000" ixy="0.00000" ixz="0.00000" iyy="0.00000" iyz="0.00000" izz="0.00000"/>
		</inertial>
		<visual>
			<origin rpy="0.00000 0.00000 0.00000" xyz="0.00000 0.00000 0.00000"/>
			<geometry>
				<sphere radius="0.02500"/>
			</geometry>
			<material name="">
				<color rgba="0.00000 0.00000 0.00000 0.50000" />
			</material>
		</visual>
		<collision>
			<origin rpy="0.00000 0.00000 0.00000" xyz="0.00000 0.00000 0.00000"/>
			<geometry>
				<sphere radius="0.02500"/>
			</geometry>
		</collision>
	</link>
	<link name="link_FLW">
		<inertial>
			<origin rpy="0.00000 0.00000 0.00000" xyz="0.00000 0.00000 0.00000"/>
			<mass value="0.06293"/>
			<inertia ixx="0.00002" ixy="0.00000" ixz="0.00000" iyy="0.00003" iyz="0.00000" izz="0.00002"/>
		</inertial>
		<visual>
			<origin rpy="1.57080 0.00000 0.00000" xyz="0.00000 0.00000 0.00000"/>
			<geometry>
				<cylinder length="0.01200" radius="0.02800"/>
			</geometry>
			<material name="">
				<color rgba="0.00000 0.00000 0.00000 0.50000" />
			</material>
		</visual>
		<collision>
			<origin rpy="1.57080 0.00000 0.00000" xyz="0.00000 0.00000 0.00000"/>
			<geometry>
				<cylinder length="0.01200" radius="0.02800"/>
			</geometry>
		</collision>
	</link>
	<link name="link_HR1">
		<inertial>
			<origin rpy="0.00000 0.00000 0.00000" xyz="0.00287 0.00035 -0.00047"/>
			<mass value="0.60318"/>
			<inertia ixx="0.00037" ixy="0.00000" ixz="0.00000" iyy="0.00065" iyz="0.00001" izz="0.00042"/>
		</inertial>
		<visual>
			<origin rpy="1.57080 0.00000 0.00000" xyz="0.00000 0.00000 0.00000"/>
			<geometry>
				<cylinder length="0.02550" radius="0.04700"/>
			</geometry>
			<material name="">
				<color rgba="0.00000 0.00000 0.00000 0.50000" />
			</material>
		</visual>
		<collision>
			<origin rpy="1.57080 0.00000 0.00000" xyz="0.00000 0.00000 0.00000"/>
			<geometry>
				<cylinder length="0.02550" radius="0.04700"/>
			</geometry>
		</collision>
	</link>
	<link name="link_HR2">
		<inertial>
			<origin rpy="0.00000 0.00000 0.00000" xyz="-0.00077 0.02622 -0.02560"/>
			<mass value="0.89043"/>
			<inertia ixx="0.00367" ixy="0.00005" ixz="-0.00008" iyy="0.00417" iyz="0.00047" izz="0.00120"/>
		</inertial>
		<visual>
			<origin rpy="0.00000 1.57080 0.00000" xyz="0.00000 0.00000 -0.12000"/>
			<geometry>
				<box size="0.24000 0.02500 0.03500"/>
			</geometry>
			<material name="">
				<color rgba="0.00000 0.00000 0.00000 0.50000" />
			</material>
		</visual>
		<visual>
			<origin rpy="1.57080 0.00000 0.00000" xyz="0.00000 0.00000 0.00000"/>
			<geometry>
				<cylinder length="0.02500" radius="0.02300"/>
			</geometry>
			<material name="">
				<color rgba="0.00000 0.00000 0.00000 0.50000" />
			</material>
		</visual>
		<visual>
			<origin rpy="1.57080 0.00000 0.00000" xyz="0.00000 0.03000 0.00000"/>
			<geometry>
				<cylinder length="0.02500" radius="0.04700"/>
			</geometry>
			<material name="">
				<color rgba="0.00000 0.00000 0.00000 0.50000" />
			</material>
		</visual>
		<collision>
			<origin rpy="0.00000 1.57080 0.00000" xyz="0.00000 0.00000 -0.12000"/>
			<geometry>
				<box size="0.24000 0.02500 0.03500"/>
			</geometry>
		</collision>
		<collision>
			<origin rpy="1.57080 0.00000 0.00000" xyz="0.00000 0.00000 0.00000"/>
			<geometry>
				<cylinder length="0.02500" radius="0.02300"/>
			</geometry>
		</collision>
		<collision>
			<origin rpy="1.57080 0.00000 0.00000" xyz="0.00000 0.03000 0.00000"/>
			<geometry>
				<cylinder length="0.02500" radius="0.04700"/>
			</geometry>
		</collision>
	</link>
	<link name="link_HR3">
		<inertial>
			<origin rpy="0.00000 0.00000 0.00000" xyz="0.00171 -0.00016 -0.08671"/>
			<mass value="0.28839"/>
			<inertia ixx="0.00208" ixy="-0.00000" ixz="0.00008" iyy="0.00210" iyz="-0.00000" izz="0.00007"/>
		</inertial>
		<visual>
			<origin rpy="0.00000 1.57080 0.00000" xyz="0.00000 0.00000 -0.15120"/>
			<geometry>
				<box size="0.34560 0.02000 0.01800"/>
			</geometry>
			<material name="">
				<color rgba="0.00000 0.00000 0.00000 0.50000" />
			</material>
		</visual>
		<collision>
			<origin rpy="0.00000 1.57080 0.00000" xyz="0.00000 0.00000 -0.15120"/>
			<geometry>
				<box size="0.34560 0.02000 0.01800"/>
			</geometry>
		</collision>
	</link>
	<link name="link_HR4">
		<inertial>
			<origin rpy="0.00000 0.00000 0.00000" xyz="0.00000 0.00000 0.00000"/>
			<mass value="0.00000"/>
			<inertia ixx="0.00000" ixy="0.00000" ixz="0.00000" iyy="0.00000" iyz="0.00000" izz="0.00000"/>
		</inertial>
		<visual>
			<origin rpy="0.00000 0.00000 0.00000" xyz="0.00000 0.00000 0.00000"/>
			<geometry>
				<sphere radius="0.02500"/>
			</geometry>
			<material name="">
				<color rgba="0.00000 0.00000 0.00000 0.50000" />
			</material>
		</visual>
		<collision>
			<origin rpy="0.00000 0.00000 0.00000" xyz="0.00000 0.00000 0.00000"/>
			<geometry>
				<sphere radius="0.02500"/>
			</geometry>
		</collision>
	</link>
	<link name="link_HRW">
		<inertial>
			<origin rpy="0.00000 0.00000 0.00000" xyz="0.00000 0.00000 0.00000"/>
			<mass value="0.12000"/>
			<inertia ixx="0.00003" ixy="0.00000" ixz="0.00000" iyy="0.00004" iyz="0.00000" izz="0.00003"/>
		</inertial>
		<visual>
			<origin rpy="1.57080 0.00000 0.00000" xyz="0.00000 0.00000 0.00000"/>
			<geometry>
				<cylinder length="0.01600" radius="0.03600"/>
			</geometry>
			<material name="">
				<color rgba="0.00000 0.00000 0.00000 0.50000" />
			</material>
		</visual>
		<collision>
			<origin rpy="1.57080 0.00000 0.00000" xyz="0.00000 0.00000 0.00000"/>
			<geometry>
				<cylinder length="0.01600" radius="0.03600"/>
			</geometry>
		</collision>
	</link>
	<link name="link_HL1">
		<inertial>
			<origin rpy="0.00000 0.00000 0.00000" xyz="0.00287 -0.00035 -0.00047"/>
			<mass value="0.60318"/>
			<inertia ixx="0.00037" ixy="-0.00000" ixz="0.00000" iyy="0.00065" iyz="-0.00001" izz="0.00042"/>
		</inertial>
		<visual>
			<origin rpy="1.57080 0.00000 0.00000" xyz="0.00000 0.00000 0.00000"/>
			<geometry>
				<cylinder length="0.02550" radius="0.04700"/>
			</geometry>
			<material name="">
				<color rgba="0.00000 0.00000 0.00000 0.50000" />
			</material>
		</visual>
		<collision>
			<origin rpy="1.57080 0.00000 0.00000" xyz="0.00000 0.00000 0.00000"/>
			<geometry>
				<cylinder length="0.02550" radius="0.04700"/>
			</geometry>
		</collision>
	</link>
	<link name="link_HL2">
		<inertial>
			<origin rpy="0.00000 0.00000 0.00000" xyz="-0.00077 -0.02622 -0.02560"/>
			<mass value="0.89043"/>
			<inertia ixx="0.00367" ixy="0.00005" ixz="0.00008" iyy="0.00417" iyz="-0.00047" izz="0.00120"/>
		</inertial>
		<visual>
			<origin rpy="0.00000 1.57080 0.00000" xyz="0.00000 0.00000 -0.12000"/>
			<geometry>
				<box size="0.24000 0.02500 0.03500"/>
			</geometry>
			<material name="">
				<color rgba="0.00000 0.00000 0.00000 0.50000" />
			</material>
		</visual>
		<visual>
			<origin rpy="1.57080 0.00000 0.00000" xyz="0.00000 0.00000 0.00000"/>
			<geometry>
				<cylinder length="0.02500" radius="0.02300"/>
			</geometry>
			<material name="">
				<color rgba="0.00000 0.00000 0.00000 0.50000" />
			</material>
		</visual>
		<visual>
			<origin rpy="1.57080 0.00000 0.00000" xyz="0.00000 -0.03000 0.00000"/>
			<geometry>
				<cylinder length="0.02500" radius="0.04700"/>
			</geometry>
			<material name="">
				<color rgba="0.00000 0.00000 0.00000 0.50000" />
			</material>
		</visual>
		<collision>
			<origin rpy="0.00000 1.57080 0.00000" xyz="0.00000 0.00000 -0.12000"/>
			<geometry>
				<box size="0.24000 0.02500 0.03500"/>
			</geometry>
		</collision>
		<collision>
			<origin rpy="1.57080 0.00000 0.00000" xyz="0.00000 0.00000 0.00000"/>
			<geometry>
				<cylinder length="0.02500" radius="0.02300"/>
			</geometry>
		</collision>
		<collision>
			<origin rpy="1.57080 0.00000 0.00000" xyz="0.00000 -0.03000 0.00000"/>
			<geometry>
				<cylinder length="0.02500" radius="0.04700"/>
			</geometry>
		</collision>
	</link>
	<link name="link_HL3">
		<inertial>
			<origin rpy="0.00000 0.00000 0.00000" xyz="0.00171 0.00016 -0.08671"/>
			<mass value="0.28839"/>
			<inertia ixx="0.00208" ixy="0.00000" ixz="0.00008" iyy="0.00210" iyz="0.00000" izz="0.00007"/>
		</inertial>
		<visual>
			<origin rpy="0.00000 1.57080 0.00000" xyz="0.00000 0.00000 -0.15120"/>
			<geometry>
				<box size="0.34560 0.02000 0.01800"/>
			</geometry>
			<material name="">
				<color rgba="0.00000 0.00000 0.00000 0.50000" />
			</material>
		</visual>
		<collision>
			<origin rpy="0.00000 1.57080 0.00000" xyz="0.00000 0.00000 -0.15120"/>
			<geometry>
				<box size="0.34560 0.02000 0.01800"/>
			</geometry>
		</collision>
	</link>
	<link name="link_HL4">
		<inertial>
			<origin rpy="0.00000 0.00000 0.00000" xyz="0.00000 0.00000 0.00000"/>
			<mass value="0.00000"/>
			<inertia ixx="0.00000" ixy="0.00000" ixz="0.00000" iyy="0.00000" iyz="0.00000" izz="0.00000"/>
		</inertial>
		<visual>
			<origin rpy="0.00000 0.00000 0.00000" xyz="0.00000 0.00000 0.00000"/>
			<geometry>
				<sphere radius="0.02500"/>
			</geometry>
			<material name="">
				<color rgba="0.00000 0.00000 0.00000 0.50000" />
			</material>
		</visual>
		<collision>
			<origin rpy="0.00000 0.00000 0.00000" xyz="0.00000 0.00000 0.00000"/>
			<geometry>
				<sphere radius="0.02500"/>
			</geometry>
		</collision>
	</link>
	<link name="link_HLW">
		<inertial>
			<origin rpy="0.00000 0.00000 0.00000" xyz="0.00000 0.00000 0.00000"/>
			<mass value="0.12000"/>
			<inertia ixx="0.00003" ixy="0.00000" ixz="0.00000" iyy="0.00004" iyz="0.00000" izz="0.00003"/>
		</inertial>
		<visual>
			<origin rpy="1.57080 0.00000 0.00000" xyz="0.00000 0.00000 0.00000"/>
			<geometry>
				<cylinder length="0.01600" radius="0.03600"/>
			</geometry>
			<material name="">
				<color rgba="0.00000 0.00000 0.00000 0.50000" />
			</material>
		</visual>
		<collision>
			<origin rpy="1.57080 0.00000 0.00000" xyz="0.00000 0.00000 0.00000"/>
			<geometry>
				<cylinder length="0.01600" radius="0.03600"/>
			</geometry>
		</collision>
	</link>
	<link name="link_front_handle">
		<inertial>
			<origin rpy="0.00000 0.00000 0.00000" xyz="0.00000 0.00000 0.00000"/>
			<mass value="0.00100"/>
			<inertia ixx="0.00000" ixy="0.00000" ixz="0.00000" iyy="0.00000" iyz="0.00000" izz="0.00000"/>
		</inertial>
		<visual>
			<origin rpy="0.00000 0.00000 0.00000" xyz="0.00000 0.00000 0.00000"/>
			<geometry>
				<sphere radius="0.00100"/>
			</geometry>
			<material name="">
				<color rgba="0.00000 0.00000 0.00000 0.50000" />
			</material>
		</visual>
		<collision>
			<origin rpy="0.00000 0.00000 0.00000" xyz="0.00000 0.00000 0.00000"/>
			<geometry>
				<sphere radius="0.00100"/>
			</geometry>
		</collision>
	</link>
	<link name="link_hind_handle">
		<inertial>
			<origin rpy="0.00000 0.00000 0.00000" xyz="0.00000 0.00000 0.00000"/>
			<mass value="0.00100"/>
			<inertia ixx="0.00000" ixy="0.00000" ixz="0.00000" iyy="0.00000" iyz="0.00000" izz="0.00000"/>
		</inertial>
		<visual>
			<origin rpy="0.00000 0.00000 0.00000" xyz="0.00000 0.00000 0.00000"/>
			<geometry>
				<sphere radius="0.00100"/>
			</geometry>
			<material name="">
				<color rgba="0.00000 0.00000 0.00000 0.50000" />
			</material>
		</visual>
		<collision>
			<origin rpy="0.00000 0.00000 0.00000" xyz="0.00000 0.00000 0.00000"/>
			<geometry>
				<sphere radius="0.00100"/>
			</geometry>
		</collision>
	</link>
	<joint name="joint_FR1" type="revolute">
		<parent link="body"/>
		<child link="link_FR1"/>
		<limit effort="18.00000" lower="-0.87200" upper="0.69700" velocity="20.00000"/>
		<dynamics damping="0.10000" friction="0.50000"/>
		<origin rpy="0.00000 0.00000 0.00000" xyz="0.19500 -0.06000 0.00000"/>
		<axis xyz="1.00000 0.00000 0.00000"/>
	</joint>
	<joint name="joint_FR2" type="revolute">
		<parent link="link_FR1"/>
		<child link="link_FR2"/>
		<limit effort="18.00000" lower="-4.36330" upper="1.22170" velocity="20.00000"/>
		<dynamics damping="0.10000" friction="0.50000"/>
		<origin rpy="0.00000 0.00000 0.00000" xyz="0.00000 -0.09000 0.00000"/>
		<axis xyz="0.00000 -1.00000 0.00000"/>
	</joint>
	<joint name="joint_FR3" type="revolute">
		<parent link="link_FR2"/>
		<child link="link_FR3"/>
		<limit effort="18.00000" lower="-2.44960" upper="2.54400" velocity="33.00000"/>
		<dynamics damping="0.10000" friction="0.50000"/>
		<origin rpy="0.00000 0.00000 0.00000" xyz="0.00000 0.00000 -0.25380"/>
		<axis xyz="0.00000 -1.00000 0.00000"/>
	</joint>
	<joint name="joint_FR4" type="fixed">
		<parent link="link_FR3"/>
		<child link="link_FR4"/>
		<dynamics damping="0.00000" friction="0.00000"/>
		<origin rpy="0.00000 0.00000 0.00000" xyz="0.00000 0.00000 -0.34560"/>
		<axis xyz="1.00000 2.00000 3.00000"/>
	</joint>
	<joint name="joint_FRW" type="fixed">
		<parent link="link_FR2"/>
		<child link="link_FRW"/>
		<dynamics damping="0.80000" friction="0.50000"/>
		<origin rpy="0.00000 0.00000 0.00000" xyz="0.00000 -0.03550 -0.25380"/>
		<axis xyz="0.00000 -1.00000 0.00000"/>
	</joint>
	<joint name="joint_FL1" type="revolute">
		<parent link="body"/>
		<child link="link_FL1"/>
		<limit effort="18.00000" lower="-0.69700" upper="0.87200" velocity="20.00000"/>
		<dynamics damping="0.10000" friction="0.50000"/>
		<origin rpy="0.00000 0.00000 0.00000" xyz="0.19500 0.06000 0.00000"/>
		<axis xyz="1.00000 0.00000 0.00000"/>
	</joint>
	<joint name="joint_FL2" type="revolute">
		<parent link="link_FL1"/>
		<child link="link_FL2"/>
		<limit effort="18.00000" lower="-4.36330" upper="1.22170" velocity="20.00000"/>
		<dynamics damping="0.10000" friction="0.50000"/>
		<origin rpy="0.00000 0.00000 0.00000" xyz="0.00000 0.09000 0.00000"/>
		<axis xyz="0.00000 -1.00000 0.00000"/>
	</joint>
	<joint name="joint_FL3" type="revolute">
		<parent link="link_FL2"/>
		<child link="link_FL3"/>
		<limit effort="18.00000" lower="-2.44960" upper="2.54400" velocity="33.00000"/>
		<dynamics damping="0.10000" friction="0.50000"/>
		<origin rpy="0.00000 0.00000 0.00000" xyz="0.00000 0.00000 -0.25380"/>
		<axis xyz="0.00000 -1.00000 0.00000"/>
	</joint>
	<joint name="joint_FL4" type="fixed">
		<parent link="link_FL3"/>
		<child link="link_FL4"/>
		<dynamics damping="0.00000" friction="0.00000"/>
		<origin rpy="0.00000 0.00000 0.00000" xyz="0.00000 0.00000 -0.34560"/>
		<axis xyz="1.00000 2.00000 3.00000"/>
	</joint>
	<joint name="joint_FLW" type="fixed">
		<parent link="link_FL2"/>
		<child link="link_FLW"/>
		<dynamics damping="0.80000" friction="0.50000"/>
		<origin rpy="0.00000 0.00000 0.00000" xyz="0.00000 0.03550 -0.25380"/>
		<axis xyz="0.00000 -1.00000 0.00000"/>
	</joint>
	<joint name="joint_HR1" type="revolute">
		<parent link="body"/>
		<child link="link_HR1"/>
		<limit effort="18.00000" lower="-0.87200" upper="0.69700" velocity="20.00000"/>
		<dynamics damping="0.10000" friction="0.50000"/>
		<origin rpy="0.00000 0.00000 0.00000" xyz="-0.19500 -0.06000 0.00000"/>
		<axis xyz="1.00000 0.00000 0.00000"/>
	</joint>
	<joint name="joint_HR2" type="revolute">
		<parent link="link_HR1"/>
		<child link="link_HR2"/>
		<limit effort="18.00000" lower="-4.36330" upper="1.22170" velocity="20.00000"/>
		<dynamics damping="0.10000" friction="0.50000"/>
		<origin rpy="0.00000 0.00000 0.00000" xyz="0.00000 -0.09000 0.00000"/>
		<axis xyz="0.00000 -1.00000 0.00000"/>
	</joint>
	<joint name="joint_HR3" type="revolute">
		<parent link="link_HR2"/>
		<child link="link_HR3"/>
		<limit effort="18.00000" lower="-2.39950" upper="2.58550" velocity="33.00000"/>
		<dynamics damping="0.10000" friction="0.50000"/>
		<origin rpy="0.00000 0.00000 0.00000" xyz="0.00000 0.00000 -0.25380"/>
		<axis xyz="0.00000 -1.00000 0.00000"/>
	</joint>
	<joint name="joint_HR4" type="fixed">
		<parent link="link_HR3"/>
		<child link="link_HR4"/>
		<dynamics damping="0.00000" friction="0.00000"/>
		<origin rpy="0.00000 0.00000 0.00000" xyz="0.00000 0.00000 -0.34560"/>
		<axis xyz="1.00000 2.00000 3.00000"/>
	</joint>
	<joint name="joint_HRW" type="fixed">
		<parent link="link_HR2"/>
		<child link="link_HRW"/>
		<dynamics damping="0.80000" friction="0.50000"/>
		<origin rpy="0.00000 1.57080 0.00000" xyz="0.00000 -0.04795 -0.25380"/>
		<axis xyz="0.00000 -1.00000 0.00000"/>
	</joint>
	<joint name="joint_HL1" type="revolute">
		<parent link="body"/>
		<child link="link_HL1"/>
		<limit effort="18.00000" lower="-0.69700" upper="0.87200" velocity="20.00000"/>
		<dynamics damping="0.10000" friction="0.50000"/>
		<origin rpy="0.00000 0.00000 0.00000" xyz="-0.19500 0.06000 0.00000"/>
		<axis xyz="1.00000 0.00000 0.00000"/>
	</joint>
	<joint name="joint_HL2" type="revolute">
		<parent link="link_HL1"/>
		<child link="link_HL2"/>
		<limit effort="18.00000" lower="-4.36330" upper="1.22170" velocity="20.00000"/>
		<dynamics damping="0.10000" friction="0.50000"/>
		<origin rpy="0.00000 0.00000 0.00000" xyz="0.00000 0.09000 0.00000"/>
		<axis xyz="0.00000 -1.00000 0.00000"/>
	</joint>
	<joint name="joint_HL3" type="revolute">
		<parent link="link_HL2"/>
		<child link="link_HL3"/>
		<limit effort="18.00000" lower="-2.39950" upper="2.58550" velocity="33.00000"/>
		<dynamics damping="0.10000" friction="0.50000"/>
		<origin rpy="0.00000 0.00000 0.00000" xyz="0.00000 0.00000 -0.25380"/>
		<axis xyz="0.00000 -1.00000 0.00000"/>
	</joint>
	<joint name="joint_HL4" type="fixed">
		<parent link="link_HL3"/>
		<child link="link_HL4"/>
		<dynamics damping="0.00000" friction="0.00000"/>
		<origin rpy="0.00000 0.00000 0.00000" xyz="0.00000 0.00000 -0.34560"/>
		<axis xyz="1.00000 2.00000 3.00000"/>
	</joint>
	<joint name="joint_HLW" type="fixed">
		<parent link="link_HL2"/>
		<child link="link_HLW"/>
		<dynamics damping="0.80000" friction="0.50000"/>
		<origin rpy="0.00000 1.57080 0.00000" xyz="0.00000 0.04795 -0.25380"/>
		<axis xyz="0.00000 -1.00000 0.00000"/>
	</joint>
	<joint name="joint_front_handle" type="fixed">
		<parent link="body"/>
		<child link="link_front_handle"/>
		<dynamics damping="0.00000" friction="0.00000"/>
		<origin rpy="0.00000 0.00000 0.00000" xyz="0.14150 0.00000 0.08500"/>
		<axis xyz="1.00000 2.00000 3.00000"/>
	</joint>
	<joint name="joint_hind_handle" type="fixed">
		<parent link="body"/>
		<child link="link_hind_handle"/>
		<dynamics damping="0.00000" friction="0.00000"/>
		<origin rpy="0.00000 0.00000 0.00000" xyz="-0.24850 0.00000 0.08500"/>
		<axis xyz="1.00000 2.00000 3.00000"/>
	</joint>
</robot>
