<?xml version="0.0" ?>
<robot name="laikago">
	<link name="chassis">
		<inertial>
			<origin rpy="0.00000 0.00000 0.00000" xyz="0.00000 0.03000 0.04379"/>
			<mass value="13.71500"/>
			<inertia ixx="0.00000" ixy="0.00000" ixz="0.00000" iyy="0.00000" iyz="0.00000" izz="0.00000"/>
		</inertial>
		<visual>
			<origin rpy="-1.57000 0.00000 0.00000" xyz="0.00000 0.00000 0.04379"/>
			<geometry>
				<mesh filename="chassis_vhacd_mod.obj" scale="1.00000 1.00000 1.00000"/>
			</geometry>
			<material name="">
				<color rgba="0.00000 0.00000 0.00000 0.50000" />
			</material>
		</visual>
		<collision>
			<origin rpy="-1.57000 0.00000 0.00000" xyz="0.00000 0.00000 0.04379"/>
			<geometry>
				<mesh filename="chassis_vhacd_mod.obj" scale="1.00000 1.00000 1.00000"/>
			</geometry>
		</collision>
	</link>
	<link name="FR_hip_motor">
		<inertial>
			<origin rpy="0.00000 0.00000 0.00000" xyz="0.02000 0.00000 0.00000"/>
			<mass value="1.09500"/>
			<inertia ixx="0.00000" ixy="0.00000" ixz="0.00000" iyy="0.00000" iyz="0.00000" izz="0.00000"/>
		</inertial>
		<visual>
			<origin rpy="0.00000 0.00000 0.00000" xyz="0.00000 0.00000 0.00000"/>
			<geometry>
				<mesh filename="hip_motor_mirror.stl" scale="1.00000 1.00000 1.00000"/>
			</geometry>
			<material name="">
				<color rgba="0.00000 0.00000 0.00000 0.50000" />
			</material>
		</visual>
		<collision>
			<origin rpy="0.00000 0.00000 0.00000" xyz="0.00000 0.00000 0.00000"/>
			<geometry>
				<mesh filename="hip_motor_mirror.stl" scale="1.00000 1.00000 1.00000"/>
			</geometry>
		</collision>
	</link>
	<link name="FR_upper_leg">
		<inertial>
			<origin rpy="0.00000 0.00000 0.00000" xyz="0.00000 -0.04000 -0.04000"/>
			<mass value="1.52700"/>
			<inertia ixx="0.00000" ixy="0.00000" ixz="0.00000" iyy="0.00000" iyz="0.00000" izz="0.00000"/>
		</inertial>
		<visual>
			<origin rpy="0.00000 0.00000 0.00000" xyz="0.00000 0.00000 0.00000"/>
			<geometry>
				<mesh filename="upper_leg_right_vhacd.obj" scale="1.00000 1.00000 1.00000"/>
			</geometry>
			<material name="">
				<color rgba="0.00000 0.00000 0.00000 0.50000" />
			</material>
		</visual>
		<collision>
			<origin rpy="0.00000 0.00000 0.00000" xyz="0.00000 0.00000 0.00000"/>
			<geometry>
				<mesh filename="upper_leg_right_vhacd.obj" scale="1.00000 1.00000 1.00000"/>
			</geometry>
		</collision>
	</link>
	<link name="FR_lower_leg">
		<inertial>
			<origin rpy="0.00000 0.00000 0.00000" xyz="0.00000 -0.16000 -0.02000"/>
			<mass value="0.24100"/>
			<inertia ixx="0.00000" ixy="0.00000" ixz="0.00000" iyy="0.00000" iyz="0.00000" izz="0.00000"/>
		</inertial>
		<visual>
			<origin rpy="0.00000 1.57079 0.00000" xyz="0.00000 0.00000 0.00000"/>
			<geometry>
				<mesh filename="lower_leg_3.stl" scale="1.00000 1.00000 1.00000"/>
			</geometry>
			<material name="">
				<color rgba="0.00000 0.00000 0.00000 0.50000" />
			</material>
		</visual>
		<collision>
			<origin rpy="0.00000 1.57079 0.00000" xyz="0.00000 0.00000 0.00000"/>
			<geometry>
				<mesh filename="lower_leg_3.stl" scale="1.00000 1.00000 1.00000"/>
			</geometry>
		</collision>
	</link>
	<link name="FL_hip_motor">
		<inertial>
			<origin rpy="0.00000 0.00000 0.00000" xyz="-0.02000 0.00000 0.00000"/>
			<mass value="1.09500"/>
			<inertia ixx="0.00000" ixy="0.00000" ixz="0.00000" iyy="0.00000" iyz="0.00000" izz="0.00000"/>
		</inertial>
		<visual>
			<origin rpy="0.00000 0.00000 0.00000" xyz="0.00000 0.00000 0.00000"/>
			<geometry>
				<mesh filename="hip_motor.stl" scale="1.00000 1.00000 1.00000"/>
			</geometry>
			<material name="">
				<color rgba="0.00000 0.00000 0.00000 0.50000" />
			</material>
		</visual>
		<collision>
			<origin rpy="0.00000 0.00000 0.00000" xyz="0.00000 0.00000 0.00000"/>
			<geometry>
				<mesh filename="hip_motor.stl" scale="1.00000 1.00000 1.00000"/>
			</geometry>
		</collision>
	</link>
	<link name="FL_upper_leg">
		<inertial>
			<origin rpy="0.00000 0.00000 0.00000" xyz="0.00000 -0.04000 -0.04000"/>
			<mass value="1.52700"/>
			<inertia ixx="0.00000" ixy="0.00000" ixz="0.00000" iyy="0.00000" iyz="0.00000" izz="0.00000"/>
		</inertial>
		<visual>
			<origin rpy="0.00000 0.00000 0.00000" xyz="0.00000 0.00000 0.00000"/>
			<geometry>
				<mesh filename="upper_leg_left_vhacd.obj" scale="1.00000 1.00000 1.00000"/>
			</geometry>
			<material name="">
				<color rgba="0.00000 0.00000 0.00000 0.50000" />
			</material>
		</visual>
		<collision>
			<origin rpy="0.00000 0.00000 0.00000" xyz="0.00000 0.00000 0.00000"/>
			<geometry>
				<mesh filename="upper_leg_left_vhacd.obj" scale="1.00000 1.00000 1.00000"/>
			</geometry>
		</collision>
	</link>
	<link name="FL_lower_leg">
		<inertial>
			<origin rpy="0.00000 0.00000 0.00000" xyz="0.00000 -0.16000 -0.02000"/>
			<mass value="0.24100"/>
			<inertia ixx="0.00000" ixy="0.00000" ixz="0.00000" iyy="0.00000" iyz="0.00000" izz="0.00000"/>
		</inertial>
		<visual>
			<origin rpy="0.00000 1.57079 0.00000" xyz="0.00000 0.00000 0.00000"/>
			<geometry>
				<mesh filename="lower_leg_3.stl" scale="1.00000 1.00000 1.00000"/>
			</geometry>
			<material name="">
				<color rgba="0.00000 0.00000 0.00000 0.50000" />
			</material>
		</visual>
		<collision>
			<origin rpy="0.00000 1.57079 0.00000" xyz="0.00000 0.00000 0.00000"/>
			<geometry>
				<mesh filename="lower_leg_3.stl" scale="1.00000 1.00000 1.00000"/>
			</geometry>
		</collision>
	</link>
	<link name="RR_hip_motor">
		<inertial>
			<origin rpy="0.00000 0.00000 0.00000" xyz="0.02000 0.00000 0.00000"/>
			<mass value="1.09500"/>
			<inertia ixx="0.00000" ixy="0.00000" ixz="0.00000" iyy="0.00000" iyz="0.00000" izz="0.00000"/>
		</inertial>
		<visual>
			<origin rpy="0.00000 0.00000 0.00000" xyz="0.00000 0.00000 0.00000"/>
			<geometry>
				<mesh filename="hip_motor_mirror.stl" scale="1.00000 1.00000 1.00000"/>
			</geometry>
			<material name="">
				<color rgba="0.00000 0.00000 0.00000 0.50000" />
			</material>
		</visual>
		<collision>
			<origin rpy="0.00000 0.00000 0.00000" xyz="0.00000 0.00000 0.00000"/>
			<geometry>
				<mesh filename="hip_motor_mirror.stl" scale="1.00000 1.00000 1.00000"/>
			</geometry>
		</collision>
	</link>
	<link name="RR_upper_leg">
		<inertial>
			<origin rpy="0.00000 0.00000 0.00000" xyz="0.00000 -0.04000 -0.04000"/>
			<mass value="1.52700"/>
			<inertia ixx="0.00000" ixy="0.00000" ixz="0.00000" iyy="0.00000" iyz="0.00000" izz="0.00000"/>
		</inertial>
		<visual>
			<origin rpy="0.00000 0.00000 0.00000" xyz="0.00000 0.00000 0.00000"/>
			<geometry>
				<mesh filename="upper_leg_right_vhacd.obj" scale="1.00000 1.00000 1.00000"/>
			</geometry>
			<material name="">
				<color rgba="0.00000 0.00000 0.00000 0.50000" />
			</material>
		</visual>
		<collision>
			<origin rpy="0.00000 0.00000 0.00000" xyz="0.00000 0.00000 0.00000"/>
			<geometry>
				<mesh filename="upper_leg_right_vhacd.obj" scale="1.00000 1.00000 1.00000"/>
			</geometry>
		</collision>
	</link>
	<link name="RR_lower_leg">
		<inertial>
			<origin rpy="0.00000 0.00000 0.00000" xyz="0.00000 -0.16000 -0.02000"/>
			<mass value="0.24100"/>
			<inertia ixx="0.00000" ixy="0.00000" ixz="0.00000" iyy="0.00000" iyz="0.00000" izz="0.00000"/>
		</inertial>
		<visual>
			<origin rpy="0.00000 1.57079 0.00000" xyz="0.00000 0.00000 0.00000"/>
			<geometry>
				<mesh filename="lower_leg_3.stl" scale="1.00000 1.00000 1.00000"/>
			</geometry>
			<material name="">
				<color rgba="0.00000 0.00000 0.00000 0.50000" />
			</material>
		</visual>
		<collision>
			<origin rpy="0.00000 1.57079 0.00000" xyz="0.00000 0.00000 0.00000"/>
			<geometry>
				<mesh filename="lower_leg_3.stl" scale="1.00000 1.00000 1.00000"/>
			</geometry>
		</collision>
	</link>
	<link name="RL_hip_motor">
		<inertial>
			<origin rpy="0.00000 0.00000 0.00000" xyz="-0.02000 0.00000 0.00000"/>
			<mass value="1.09500"/>
			<inertia ixx="0.00000" ixy="0.00000" ixz="0.00000" iyy="0.00000" iyz="0.00000" izz="0.00000"/>
		</inertial>
		<visual>
			<origin rpy="0.00000 0.00000 0.00000" xyz="0.00000 0.00000 0.00000"/>
			<geometry>
				<mesh filename="hip_motor.stl" scale="1.00000 1.00000 1.00000"/>
			</geometry>
			<material name="">
				<color rgba="0.00000 0.00000 0.00000 0.50000" />
			</material>
		</visual>
		<collision>
			<origin rpy="0.00000 0.00000 0.00000" xyz="0.00000 0.00000 0.00000"/>
			<geometry>
				<mesh filename="hip_motor.stl" scale="1.00000 1.00000 1.00000"/>
			</geometry>
		</collision>
	</link>
	<link name="RL_upper_leg">
		<inertial>
			<origin rpy="0.00000 0.00000 0.00000" xyz="0.00000 -0.04000 -0.04000"/>
			<mass value="1.52700"/>
			<inertia ixx="0.00000" ixy="0.00000" ixz="0.00000" iyy="0.00000" iyz="0.00000" izz="0.00000"/>
		</inertial>
		<visual>
			<origin rpy="0.00000 0.00000 0.00000" xyz="0.00000 0.00000 0.00000"/>
			<geometry>
				<mesh filename="upper_leg_left_vhacd.obj" scale="1.00000 1.00000 1.00000"/>
			</geometry>
			<material name="">
				<color rgba="0.00000 0.00000 0.00000 0.50000" />
			</material>
		</visual>
		<collision>
			<origin rpy="0.00000 0.00000 0.00000" xyz="0.00000 0.00000 0.00000"/>
			<geometry>
				<mesh filename="upper_leg_left_vhacd.obj" scale="1.00000 1.00000 1.00000"/>
			</geometry>
		</collision>
	</link>
	<link name="RL_lower_leg">
		<inertial>
			<origin rpy="0.00000 0.00000 0.00000" xyz="0.00000 -0.16000 -0.02000"/>
			<mass value="0.24100"/>
			<inertia ixx="0.00000" ixy="0.00000" ixz="0.00000" iyy="0.00000" iyz="0.00000" izz="0.00000"/>
		</inertial>
		<visual>
			<origin rpy="0.00000 1.57079 0.00000" xyz="0.00000 0.00000 0.00000"/>
			<geometry>
				<mesh filename="lower_leg_3.stl" scale="1.00000 1.00000 1.00000"/>
			</geometry>
			<material name="">
				<color rgba="0.00000 0.00000 0.00000 0.50000" />
			</material>
		</visual>
		<collision>
			<origin rpy="0.00000 1.57079 0.00000" xyz="0.00000 0.00000 0.00000"/>
			<geometry>
				<mesh filename="lower_leg_3.stl" scale="1.00000 1.00000 1.00000"/>
			</geometry>
		</collision>
	</link>
	<link name="toeRL">
		<inertial>
			<origin rpy="0.00000 0.00000 0.00000" xyz="0.00000 0.00000 0.00000"/>
			<mass value="0.10000"/>
			<inertia ixx="0.00003" ixy="0.00000" ixz="0.00000" iyy="0.00003" iyz="0.00000" izz="0.00003"/>
		</inertial>
		<visual>
			<origin rpy="0.00000 0.00000 0.00000" xyz="0.00000 0.00000 0.00000"/>
			<geometry>
				<sphere radius="0.03000"/>
			</geometry>
			<material name="">
				<color rgba="0.00000 0.00000 0.00000 0.50000" />
			</material>
		</visual>
		<collision>
			<origin rpy="0.00000 0.00000 0.00000" xyz="0.00000 0.00000 0.00000"/>
			<geometry>
				<sphere radius="0.03000"/>
			</geometry>
		</collision>
	</link>
	<link name="toeRR">
		<inertial>
			<origin rpy="0.00000 0.00000 0.00000" xyz="0.00000 0.00000 0.00000"/>
			<mass value="0.10000"/>
			<inertia ixx="0.00003" ixy="0.00000" ixz="0.00000" iyy="0.00003" iyz="0.00000" izz="0.00003"/>
		</inertial>
		<visual>
			<origin rpy="0.00000 0.00000 0.00000" xyz="0.00000 0.00000 0.00000"/>
			<geometry>
				<sphere radius="0.03000"/>
			</geometry>
			<material name="">
				<color rgba="0.00000 0.00000 0.00000 0.50000" />
			</material>
		</visual>
		<collision>
			<origin rpy="0.00000 0.00000 0.00000" xyz="0.00000 0.00000 0.00000"/>
			<geometry>
				<sphere radius="0.03000"/>
			</geometry>
		</collision>
	</link>
	<link name="toeFL">
		<inertial>
			<origin rpy="0.00000 0.00000 0.00000" xyz="0.00000 0.00000 0.00000"/>
			<mass value="0.10000"/>
			<inertia ixx="0.00003" ixy="0.00000" ixz="0.00000" iyy="0.00003" iyz="0.00000" izz="0.00003"/>
		</inertial>
		<visual>
			<origin rpy="0.00000 0.00000 0.00000" xyz="0.00000 0.00000 0.00000"/>
			<geometry>
				<sphere radius="0.03000"/>
			</geometry>
			<material name="">
				<color rgba="0.00000 0.00000 0.00000 0.50000" />
			</material>
		</visual>
		<collision>
			<origin rpy="0.00000 0.00000 0.00000" xyz="0.00000 0.00000 0.00000"/>
			<geometry>
				<sphere radius="0.03000"/>
			</geometry>
		</collision>
	</link>
	<link name="toeFR">
		<inertial>
			<origin rpy="0.00000 0.00000 0.00000" xyz="0.00000 0.00000 0.00000"/>
			<mass value="0.10000"/>
			<inertia ixx="0.00003" ixy="0.00000" ixz="0.00000" iyy="0.00003" iyz="0.00000" izz="0.00003"/>
		</inertial>
		<visual>
			<origin rpy="0.00000 0.00000 0.00000" xyz="0.00000 0.00000 0.00000"/>
			<geometry>
				<sphere radius="0.03000"/>
			</geometry>
			<material name="">
				<color rgba="0.00000 0.00000 0.00000 0.50000" />
			</material>
		</visual>
		<collision>
			<origin rpy="0.00000 0.00000 0.00000" xyz="0.00000 0.00000 0.00000"/>
			<geometry>
				<sphere radius="0.03000"/>
			</geometry>
		</collision>
	</link>
	<joint name="FR_hip_motor_2_chassis_joint" type="revolute">
		<parent link="chassis"/>
		<child link="FR_hip_motor"/>
		<limit effort="100.00000" lower="-3.14000" upper="3.14000" velocity="100.00000"/>
		<dynamics damping="0.00000" friction="0.00000"/>
		<origin rpy="0.00000 0.00000 0.00000" xyz="-0.08171 0.00000 0.24289"/>
		<axis xyz="0.00000 0.00000 -1.00000"/>
	</joint>
	<joint name="FR_upper_leg_2_hip_motor_joint" type="revolute">
		<parent link="FR_hip_motor"/>
		<child link="FR_upper_leg"/>
		<limit effort="100.00000" lower="-3.14000" upper="3.14000" velocity="100.00000"/>
		<dynamics damping="0.00000" friction="0.00000"/>
		<origin rpy="0.00000 0.00000 0.00000" xyz="-0.05357 0.00000 0.00000"/>
		<axis xyz="1.00000 0.00000 0.00000"/>
	</joint>
	<joint name="FR_lower_leg_2_upper_leg_joint" type="revolute">
		<parent link="FR_upper_leg"/>
		<child link="FR_lower_leg"/>
		<limit effort="100.00000" lower="-3.14000" upper="3.14000" velocity="100.00000"/>
		<dynamics damping="0.00000" friction="0.00000"/>
		<origin rpy="0.00000 0.00000 0.00000" xyz="0.02069 -0.20833 -0.14220"/>
		<axis xyz="1.00000 0.00000 0.00000"/>
	</joint>
	<joint name="FL_hip_motor_2_chassis_joint" type="revolute">
		<parent link="chassis"/>
		<child link="FL_hip_motor"/>
		<limit effort="100.00000" lower="-3.14000" upper="3.14000" velocity="100.00000"/>
		<dynamics damping="0.00000" friction="0.00000"/>
		<origin rpy="0.00000 0.00000 0.00000" xyz="0.08171 0.00000 0.24289"/>
		<axis xyz="0.00000 0.00000 1.00000"/>
	</joint>
	<joint name="FL_upper_leg_2_hip_motor_joint" type="revolute">
		<parent link="FL_hip_motor"/>
		<child link="FL_upper_leg"/>
		<limit effort="100.00000" lower="-3.14000" upper="3.14000" velocity="100.00000"/>
		<dynamics damping="0.00000" friction="0.00000"/>
		<origin rpy="0.00000 0.00000 0.00000" xyz="0.05586 0.00000 0.00000"/>
		<axis xyz="1.00000 0.00000 0.00000"/>
	</joint>
	<joint name="FL_lower_leg_2_upper_leg_joint" type="revolute">
		<parent link="FL_upper_leg"/>
		<child link="FL_lower_leg"/>
		<limit effort="100.00000" lower="-3.14000" upper="3.14000" velocity="100.00000"/>
		<dynamics damping="0.00000" friction="0.00000"/>
		<origin rpy="0.00000 0.00000 0.00000" xyz="-0.02069 -0.20833 -0.14220"/>
		<axis xyz="1.00000 0.00000 0.00000"/>
	</joint>
	<joint name="RR_hip_motor_2_chassis_joint" type="revolute">
		<parent link="chassis"/>
		<child link="RR_hip_motor"/>
		<limit effort="100.00000" lower="-3.14000" upper="3.14000" velocity="100.00000"/>
		<dynamics damping="0.00000" friction="0.00000"/>
		<origin rpy="0.00000 0.00000 0.00000" xyz="-0.08171 0.00000 -0.19440"/>
		<axis xyz="0.00000 0.00000 -1.00000"/>
	</joint>
	<joint name="RR_upper_leg_2_hip_motor_joint" type="revolute">
		<parent link="RR_hip_motor"/>
		<child link="RR_upper_leg"/>
		<limit effort="100.00000" lower="-3.14000" upper="3.14000" velocity="100.00000"/>
		<dynamics damping="0.00000" friction="0.00000"/>
		<origin rpy="0.00000 0.00000 0.00000" xyz="-0.05357 0.00000 0.00000"/>
		<axis xyz="1.00000 0.00000 0.00000"/>
	</joint>
	<joint name="RR_lower_leg_2_upper_leg_joint" type="revolute">
		<parent link="RR_upper_leg"/>
		<child link="RR_lower_leg"/>
		<limit effort="100.00000" lower="-3.14000" upper="3.14000" velocity="100.00000"/>
		<dynamics damping="0.00000" friction="0.00000"/>
		<origin rpy="0.00000 0.00000 0.00000" xyz="0.02069 -0.20833 -0.14220"/>
		<axis xyz="1.00000 0.00000 0.00000"/>
	</joint>
	<joint name="RL_hip_motor_2_chassis_joint" type="revolute">
		<parent link="chassis"/>
		<child link="RL_hip_motor"/>
		<limit effort="100.00000" lower="-3.14000" upper="3.14000" velocity="100.00000"/>
		<dynamics damping="0.00000" friction="0.00000"/>
		<origin rpy="0.00000 0.00000 0.00000" xyz="0.08171 0.00000 -0.19440"/>
		<axis xyz="0.00000 0.00000 1.00000"/>
	</joint>
	<joint name="RL_upper_leg_2_hip_motor_joint" type="revolute">
		<parent link="RL_hip_motor"/>
		<child link="RL_upper_leg"/>
		<limit effort="100.00000" lower="-3.14000" upper="3.14000" velocity="100.00000"/>
		<dynamics damping="0.00000" friction="0.00000"/>
		<origin rpy="0.00000 0.00000 0.00000" xyz="0.05586 0.00000 0.00000"/>
		<axis xyz="1.00000 0.00000 0.00000"/>
	</joint>
	<joint name="RL_lower_leg_2_upper_leg_joint" type="revolute">
		<parent link="RL_upper_leg"/>
		<child link="RL_lower_leg"/>
		<limit effort="100.00000" lower="-3.14000" upper="3.14000" velocity="100.00000"/>
		<dynamics damping="0.00000" friction="0.00000"/>
		<origin rpy="0.00000 0.00000 0.00000" xyz="-0.02069 -0.20833 -0.14220"/>
		<axis xyz="1.00000 0.00000 0.00000"/>
	</joint>
	<joint name="jtoeRL" type="fixed">
		<parent link="RL_lower_leg"/>
		<child link="toeRL"/>
		<dynamics damping="0.00000" friction="0.00000"/>
		<origin rpy="1.00000 2.00000 3.00000" xyz="0.00000 -0.25000 -0.02200"/>
		<axis xyz="1.00000 2.00000 3.00000"/>
	</joint>
	<joint name="jtoeRR" type="fixed">
		<parent link="RR_lower_leg"/>
		<child link="toeRR"/>
		<dynamics damping="0.00000" friction="0.00000"/>
		<origin rpy="1.00000 2.00000 3.00000" xyz="0.00000 -0.25000 -0.02200"/>
		<axis xyz="1.00000 2.00000 3.00000"/>
	</joint>
	<joint name="jtoeFL" type="fixed">
		<parent link="FL_lower_leg"/>
		<child link="toeFL"/>
		<dynamics damping="0.00000" friction="0.00000"/>
		<origin rpy="1.00000 2.00000 3.00000" xyz="0.00000 -0.25000 -0.02200"/>
		<axis xyz="1.00000 2.00000 3.00000"/>
	</joint>
	<joint name="jtoeFR" type="fixed">
		<parent link="FR_lower_leg"/>
		<child link="toeFR"/>
		<dynamics damping="0.00000" friction="0.00000"/>
		<origin rpy="1.00000 2.00000 3.00000" xyz="0.00000 -0.25000 -0.02200"/>
		<axis xyz="1.00000 2.00000 3.00000"/>
	</joint>
</robot>
