<?xml version="1.0" encoding="utf-8"?>
<!-- This URDF was automatically created by SolidWorks to URDF Exporter! Originally created by Stephen Brawner (brawner@gmail.com) 
     Commit Version: 1.6.0-1-g15f4949  Build Version: 1.6.7594.29634
     For more information, please see http://wiki.ros.org/sw_urdf_exporter -->
<robot name="max_waist">

  <link
    name="body_f">
    <inertial>
      <origin
        xyz="-0.01298060 0.00000253 0.00097666"
        rpy="0 0 0" />
      <mass
        value="2.51422699" />
      <inertia
       ixx="0.00878229"
        ixy="0.00000037"
        ixz="0.00029661"
        iyy="0.01110071"
        iyz="-0.00000008"
        izz="0.01556871" />
    </inertial>
    <visual>
      <origin
        xyz="0 0 0"
        rpy="0 0 0" />
      <geometry>
        <mesh
          filename="package://max_waist/meshes/body_f.STL" />
      </geometry>
      <material
        name="">
        <color
          rgba="0 0 0 1" />
      </material>
    </visual>
    <collision>
      <origin
        xyz="0 0 0"
        rpy="0 0 0" />
      <geometry>
        <mesh
          filename="package://max_waist/meshes/body_f.STL" />
      </geometry>
    </collision>
  </link>

  <link
    name="FR1">
    <inertial>
      <origin
        xyz="-0.00286541 0.00031671 -0.00046653"
        rpy="0 0 0" />
      <mass
        value="0.60318142" />
      <inertia
        ixx="0.00036534"
        ixy="-0.00000156"
        ixz="-0.00000493"
        iyy="0.00064755"
        iyz="0.00000517"
        izz="0.00041528" />
    </inertial>
    <visual>
      <origin
        xyz="0 0 0"
        rpy="0 0 0" />
      <geometry>
        <mesh
          filename="package://max_waist/meshes/FR1.STL" />
      </geometry>
      <material
        name="">
        <color
          rgba="0.16 0.14 0.13 1" />
      </material>
    </visual>
    <collision>
      <origin
        xyz="0 0 0"
        rpy="0 0 0" />
      <geometry>
        <mesh
          filename="package://max_waist/meshes/FR1.STL" />
      </geometry>
    </collision>
  </link>

  <joint
    name="joint_FR1"
    type="revolute">
    <origin
      xyz="0.052 -0.059 0"
      rpy="0 0 0" />
    <parent
      link="body_f" />
    <child
      link="FR1" />
    <axis
      xyz="1 0 0" />
    <limit
      lower="-3.14"
      upper="3.14"
      effort="0"
      velocity="0" />
  </joint>

  <link
    name="FR2">
    <inertial>
      <origin
        xyz="-0.00074601 0.02723585 -0.02385041"
        rpy="0 0 0" />
      <mass
        value="0.87782621" />
      <inertia
        ixx="0.00362810"
        ixy="-0.00000033"
        ixz="0.00001632"
        iyy="0.00369602"
        iyz="0.00052212"
        izz="0.00075378" />
    </inertial>
    <visual>
      <origin
        xyz="0 0 0"
        rpy="0 0 0" />
      <geometry>
        <mesh
          filename="package://max_waist/meshes/FR2.STL" />
      </geometry>
      <material
        name="">
        <color
          rgba="1 1 1 1" />
      </material>
    </visual>
    <collision>
      <origin
        xyz="0 0 0"
        rpy="0 0 0" />
      <geometry>
        <mesh
          filename="package://max_waist/meshes/FR2.STL" />
      </geometry>
    </collision>
  </link>

  <joint
    name="joint_FR2"
    type="revolute">
    <origin
      xyz="0 -0.0892499796735986 0"
      rpy="0 0 0" />
    <parent
      link="FR1" />
    <child
      link="FR2" />
    <axis
      xyz="0 -1 0" />
    <limit
      lower="-3.14"
      upper="3.14"
      effort="0"
      velocity="0" />
  </joint>

  <link
    name="FR3">
    <inertial>
      <origin
       xyz="0.00310767 0.00000641 -0.09671462"
        rpy="0 0 0" />
      <mass
        value="0.16887830" />
      <inertia
        ixx="0.00151915"
        ixy="0"
        ixz="-0.00001894"
        iyy="0.00153030"
        iyz="-0.00000013"
        izz="0.00003100" />
    </inertial>
    <visual>
      <origin
        xyz="0 0 0"
        rpy="0 0 0" />
      <geometry>
        <mesh
          filename="package://max_waist/meshes/FR3.STL" />
      </geometry>
      <material
        name="">
        <color
          rgba="0.16 0.14 0.13 1" />
      </material>
    </visual>
    <collision>
      <origin
        xyz="0 0 0"
        rpy="0 0 0" />
      <geometry>
        <mesh
          filename="package://max_waist/meshes/FR3.STL" />
      </geometry>
    </collision>
  </link>

  <joint
    name="joint_FR3"
    type="revolute">
    <origin
      xyz="0 0 -0.2115"
      rpy="0 0.0600798926534666 0" />
    <parent
      link="FR2" />
    <child
      link="FR3" />
    <axis
      xyz="0 -1 0" />
    <limit
      lower="-3.14"
      upper="3.14"
      effort="0"
      velocity="0" />
  </joint>

  <link
    name="FRW">
    <inertial>
      <origin
        xyz="0 0 0"
        rpy="0 0 0" />
      <mass
        value="0.08894981" />
      <inertia
        ixx="0.00002346"
        ixy="0"
        ixz="0"
        iyy="0.00003807"
        iyz="0"
        izz="0.00002346" />
    </inertial>
    <visual>
      <origin
        xyz="0 0 0"
        rpy="0 0 0" />
      <geometry>
        <mesh
          filename="package://max_waist/meshes/FRW.STL" />
      </geometry>
      <material
        name="">
        <color
          rgba="0.16 0.14 0.13 1" />
      </material>
    </visual>
    <collision>
      <origin
        xyz="0 0 0"
        rpy="0 0 0" />
      <geometry>
        <mesh
          filename="package://max_waist/meshes/FRW.STL" />
      </geometry>
    </collision>
  </link>

  <joint
    name="joint_FRW"
    type="continuous">
    <origin
      xyz="0 -0.0355000231257846 -0.2115"
      rpy="0 0.00587255903351753 0" />
    <parent
      link="FR2" />
    <child
      link="FRW" />
    <axis
      xyz="0 -1 0" />
  </joint>

  <link
    name="FL1">
    <inertial>
      <origin
        xyz="-0.00286541 -0.00031671 -0.00046623"
        rpy="0 0 0" />
      <mass
        value="0.60318142" />
      <inertia
        ixx="0.00036534"
        ixy="0.00000156"
        ixz="-0.00000493"
        iyy="0.00064755"
        iyz="-0.00000517"
        izz="0.00041528" />
    </inertial>
    <visual>
      <origin
        xyz="0 0 0"
        rpy="0 0 0" />
      <geometry>
        <mesh
          filename="package://max_waist/meshes/FL1.STL" />
      </geometry>
      <material
        name="">
        <color
          rgba="0.16 0.14 0.13 1" />
      </material>
    </visual>
    <collision>
      <origin
        xyz="0 0 0"
        rpy="0 0 0" />
      <geometry>
        <mesh
          filename="package://max_waist/meshes/FL1.STL" />
      </geometry>
    </collision>
  </link>

  <joint
    name="joint_FL1"
    type="revolute">
    <origin
      xyz="0.052 0.059 0"
      rpy="0 0 0" />
    <parent
      link="body_f" />
    <child
      link="FL1" />
    <axis
      xyz="1 0 0" />
    <limit
      lower="-3.14"
      upper="3.14"
      effort="0"
      velocity="0" />
  </joint>

  <link
    name="FL2">
    <inertial>
      <origin
        xyz="-0.00074605 -0.02723589 -0.02385255"
        rpy="0 0 0" />
      <mass
        value="0.87782435" />
      <inertia
        ixx="0.00362811"
        ixy="0.00000033"
        ixz="0.00001629"
        iyy="0.00369603"
        iyz="-0.00052216"
        izz="0.00075378" />
    </inertial>
    <visual>
      <origin
        xyz="0 0 0"
        rpy="0 0 0" />
      <geometry>
        <mesh
          filename="package://max_waist/meshes/FL2.STL" />
      </geometry>
      <material
        name="">
        <color
          rgba="1 1 1 1" />
      </material>
    </visual>
    <collision>
      <origin
        xyz="0 0 0"
        rpy="0 0 0" />
      <geometry>
        <mesh
          filename="package://max_waist/meshes/FL2.STL" />
      </geometry>
    </collision>
  </link>

  <joint
    name="joint_FL2"
    type="revolute">
    <origin
      xyz="0 0.0892499796735975 0"
      rpy="0 0 0" />
    <parent
      link="FL1" />
    <child
      link="FL2" />
    <axis
      xyz="0 -1 0" />
    <limit
      lower="-3.14"
      upper="3.14"
      effort="0"
      velocity="0" />
  </joint>

  <link
    name="FL3">
    <inertial>
      <origin
        xyz="0.00310767 0.00000641 -0.09671462"
        rpy="0 0 0" />
      <mass
        value="0.16887830" />
      <inertia
        ixx="0.00151915"
        ixy="0"
        ixz="-0.00001894"
        iyy="0.00153030"
        iyz="-0.00000013"
        izz="0.00003100" />
    </inertial>
    <visual>
      <origin
        xyz="0 0 0"
        rpy="0 0 0" />
      <geometry>
        <mesh
          filename="package://max_waist/meshes/FL3.STL" />
      </geometry>
      <material
        name="">
        <color
          rgba="0.16 0.14 0.13 1" />
      </material>
    </visual>
    <collision>
      <origin
        xyz="0 0 0"
        rpy="0 0 0" />
      <geometry>
        <mesh
          filename="package://max_waist/meshes/FL3.STL" />
      </geometry>
    </collision>
  </link>

  <joint
    name="joint_FL3"
    type="revolute">
    <origin
      xyz="0 0 -0.2115"
      rpy="0 0.06008 0" />
    <parent
      link="FL2" />
    <child
      link="FL3" />
    <axis
      xyz="0 -1 0" />
    <limit
      lower="-3.14"
      upper="3.14"
      effort="0"
      velocity="0" />
  </joint>

  <link
    name="FLW">
    <inertial>
     <origin
        xyz="0 0 0"
        rpy="0 0 0" />
      <mass
        value="0.08894981" />
      <inertia
        ixx="0.00002346"
        ixy="0"
        ixz="0"
        iyy="0.00003807"
        iyz="0"
        izz="0.00002346" />
    </inertial>
    <visual>
      <origin
        xyz="0 0 0"
        rpy="0 0 0" />
      <geometry>
        <mesh
          filename="package://max_waist/meshes/FLW.STL" />
      </geometry>
      <material
        name="">
        <color
          rgba="0.16 0.14 0.13 1" />
      </material>
    </visual>
    <collision>
      <origin
        xyz="0 0 0"
        rpy="0 0 0" />
      <geometry>
        <mesh
          filename="package://max_waist/meshes/FLW.STL" />
      </geometry>
    </collision>
  </link>

  <joint
    name="joint_FLW"
    type="continuous">
    <origin
      xyz="0 0.0355000231257848 -0.2115"
      rpy="0 -0.343243420765516 0" />
    <parent
      link="FL2" />
    <child
      link="FLW" />
    <axis
      xyz="0 -1 0" />
  </joint>

  <link
    name="UJ1">
    <inertial>
      <origin
       xyz="-0.01762533 0 0"
        rpy="0 0 0" />
      <mass
        value="0.06038472" />
      <inertia
        ixx="0.00003952"
        ixy="0"
        ixz="0"
        iyy="0.00002728"
        iyz="0"
        izz="0.00004052" />
    </inertial>
    <visual>
      <origin
        xyz="0 0 0"
        rpy="0 0 0" />
      <geometry>
        <mesh
          filename="package://max_waist/meshes/UJ1.STL" />
      </geometry>
      <material
        name="">
        <color
          rgba="1 0 0 1" />
      </material>
    </visual>
    <collision>
      <origin
        xyz="0 0 0"
        rpy="0 0 0" />
      <geometry>
        <mesh
          filename="package://max_waist/meshes/UJ1.STL" />
      </geometry>
    </collision>
  </link>

  <joint
    name="joint_UJ1"
    type="revolute">
    <origin
      xyz="-0.0625 0 0"
      rpy="0 0 0" />
    <parent
      link="body_f" />
    <child
      link="UJ1" />
    <axis
      xyz="1 0 0" />
    <limit
      lower="-3.14"
      upper="3.14"
      effort="0"
      velocity="0" />
  </joint>

   <link
    name="UJ2">
    <inertial>
      <origin
        xyz="0 0 0"
        rpy="0 0 0" />
      <mass
        value="0.03926619" />
      <inertia
        ixx="0.00000805"
        ixy="0"
        ixz="0"
        iyy="0.00000829"
        iyz="0"
        izz="0.00000444" />
    </inertial>
    <visual>
      <origin
        xyz="0 0 0"
        rpy="0 0 0" />
      <geometry>
        <mesh
          filename="package://max_waist/meshes/UJ2.STL" />
      </geometry>
      <material
        name="">
        <color
          rgba="1 0 0 1" />
      </material>
    </visual>
    <collision>
      <origin
        xyz="0 0 0"
        rpy="0 0 0" />
      <geometry>
        <mesh
          filename="package://max_waist/meshes/UJ2.STL" />
      </geometry>
    </collision>
  </link>

  <joint
    name="joint_UJ2"
    type="revolute">
    <origin
      xyz="-0.043 0 0"
      rpy="0 0 0" />
    <parent
      link="UJ1" />
    <child
      link="UJ2" />
    <axis
      xyz="0 -1 0" />
    <limit
      lower="-3.14"
      upper="3.14"
      effort="0"
      velocity="0" />
  </joint>

  <link
    name="UJ3">
    <inertial>
      <origin
        xyz="-0.03490421 0 0"
        rpy="0 0 0" />
      <mass
        value="0.05918711" />
      <inertia
        ixx="0.00003678"
        ixy="0"
        ixz="0"
        iyy="0.00010362"
        iyz="0"
        izz="0.00009693" />
    </inertial>
    <visual>
      <origin
        xyz="0 0 0"
        rpy="0 0 0" />
      <geometry>
        <mesh
          filename="package://max_waist/meshes/UJ3.STL" />
      </geometry>
      <material
        name="">
        <color
          rgba="1 0 0 1" />
      </material>
    </visual>
    <collision>
      <origin
        xyz="0 0 0"
        rpy="0 0 0" />
      <geometry>
        <mesh
          filename="package://max_waist/meshes/UJ3.STL" />
      </geometry>
    </collision>
  </link>

  <joint
    name="joint_UJ3"
    type="revolute">
    <origin
      xyz="0 0 0"
      rpy="0 0 0" />
    <parent
      link="UJ2" />
    <child
      link="UJ3" />
    <axis
      xyz="0 0 1" />
    <limit
      lower="-3.14"
      upper="3.14"
      effort="0"
      velocity="0" />
  </joint>

  <link
    name="body_m">
    <inertial>
      <origin
        xyz="0 0 0"
        rpy="0 0 0" />
      <mass
        value="1.00866797" />
      <inertia
        ixx="0.00261098"
        ixy="0"
        ixz="0"
        iyy="0.00107483"
        iyz="0"
        izz="0.00208697" />
    </inertial>
    <visual>
      <origin
        xyz="0 0 0"
        rpy="0 0 0" />
      <geometry>
        <mesh
          filename="package://max_waist/meshes/body_m.STL" />
      </geometry>
      <material
        name="">
        <color
          rgba="0.753 0.753 0.753 1" />
      </material>
    </visual>
    <collision>
      <origin
        xyz="0 0 0"
        rpy="0 0 0" />
      <geometry>
        <mesh
          filename="package://max_waist/meshes/body_m.STL" />
      </geometry>
    </collision>
  </link>

  <joint
    name="joint_body_m"
    type="fixed">
    <origin
      xyz="-0.0479999999999998 0 0"
      rpy="0 0 0" />
    <parent
      link="UJ3" />
    <child
      link="body_m" />
    <axis
      xyz="0 0 0" />
  </joint>

  <link
    name="UJ4">
    <inertial>
      <origin
        xyz="-0.01309579 0 0"
        rpy="0 0 0" />
      <mass
        value="0.05918711" />
      <inertia
        ixx="0.00003678"
        ixy="0"
        ixz="0"
        iyy="0.00003152"
        iyz="0"
        izz="0.00003497" />
    </inertial>
    <visual>
      <origin
        xyz="0 0 0"
        rpy="0 0 0" />
      <geometry>
        <mesh
          filename="package://max_waist/meshes/UJ4.STL" />
      </geometry>
      <material
        name="">
        <color
          rgba="1 0 0 1" />
      </material>
    </visual>
    <collision>
      <origin
        xyz="0 0 0"
        rpy="0 0 0" />
      <geometry>
        <mesh
          filename="package://max_waist/meshes/UJ4.STL" />
      </geometry>
    </collision>
  </link>

  <joint
    name="joint_UJ4"
    type="revolute">
    <origin
      xyz="-0.048 0 0"
      rpy="0 0 0" />
    <parent
      link="UJ3" />
    <child
      link="UJ4" />
    <axis
      xyz="1 0 0" />
    <limit
      lower="-3.14"
      upper="3.14"
      effort="0"
      velocity="0" />
  </joint>

  <link
    name="UJ5">
    <inertial>
       <origin
        xyz="0 0 0"
        rpy="0 0 0" />
      <mass
        value="0.03926619" />
      <inertia
        ixx="0.00000805"
        ixy="0"
        ixz="0"
        iyy="0.00000829"
        iyz="0"
        izz="0.00000444" />
    </inertial>
    <visual>
      <origin
        xyz="0 0 0"
        rpy="0 0 0" />
      <geometry>
        <mesh
          filename="package://max_waist/meshes/UJ5.STL" />
      </geometry>
      <material
        name="">
        <color
          rgba="1 0 0 1" />
      </material>
    </visual>
    <collision>
      <origin
        xyz="0 0 0"
        rpy="0 0 0" />
      <geometry>
        <mesh
          filename="package://max_waist/meshes/UJ5.STL" />
      </geometry>
    </collision>
  </link>

  <joint
    name="joint_UJ5"
    type="revolute">
    <origin
      xyz="-0.048 0 0"
      rpy="0 0 0" />
    <parent
      link="UJ4" />
    <child
      link="UJ5" />
    <axis
      xyz="0 0 1" />
    <limit
      lower="-3.14"
      upper="3.14"
      effort="0"
      velocity="0" />
  </joint>

  <link
    name="UJ6">
    <inertial>
      <origin
        xyz="-0.02537467 0 0"
        rpy="0 0 0" />
      <mass
        value="0.06038472" />
      <inertia
        ixx="0.00003952"
        ixy="0"
        ixz="0"
        iyy="0.00002728"
        iyz="0"
        izz="0.00004052" />
    </inertial>
    <visual>
      <origin
        xyz="0 0 0"
        rpy="0 0 0" />
      <geometry>
        <mesh
          filename="package://max_waist/meshes/UJ6.STL" />
      </geometry>
      <material
        name="">
        <color
          rgba="1 0 0 1" />
      </material>
    </visual>
    <collision>
      <origin
        xyz="0 0 0"
        rpy="0 0 0" />
      <geometry>
        <mesh
          filename="package://max_waist/meshes/UJ6.STL" />
      </geometry>
    </collision>
  </link>

  <joint
    name="joint_UJ6"
    type="revolute">
    <origin
      xyz="0 0 0"
      rpy="0 0 0" />
    <parent
      link="UJ5" />
    <child
      link="UJ6" />
    <axis
      xyz="0 -1 0" />
    <limit
      lower="-3.14"
      upper="3.14"
      effort="0"
      velocity="0" />
  </joint>

  <link
    name="body_h">
    <inertial>
      <origin
         xyz="-0.01928196 0 0"
        rpy="0 0 0" />
      <mass
        value="2.20234128" />
      <inertia
        ixx="0.00933241"
        ixy="0"
        ixz="0.00000022"
        iyy="0.00349245"
        iyz="0"
        izz="0.00915070" />
    </inertial>
    <visual>
      <origin
        xyz="0 0 0"
        rpy="0 0 0" />
      <geometry>
        <mesh
          filename="package://max_waist/meshes/body_h.STL" />
      </geometry>
      <material
        name="">
        <color
          rgba="0 0 0 1" />
      </material>
    </visual>
    <collision>
      <origin
        xyz="0 0 0"
        rpy="0 0 0" />
      <geometry>
        <mesh
          filename="package://max_waist/meshes/body_h.STL" />
      </geometry>
    </collision>
  </link>

  <joint
    name="joint_body_h"
    type="fixed">
    <origin
      xyz="-0.043 0 0"
      rpy="0 0 0" />
    <parent
      link="UJ6" />
    <child
      link="body_h" />
    <axis
      xyz="0 0 0" />
  </joint>

  <link
    name="HR1">
    <inertial>
      <origin
        xyz="0.00286963905621312 0.000345855477050044 -0.000466915036813879"
        rpy="0 0 0" />
      <mass
        value="0.60318142" />
      <inertia
        ixx="0.00036534"
        ixy="0.00000156"
        ixz="0.00000493"
        iyy="0.00064755"
        iyz="0.00000517"
        izz="0.00041528" />
    </inertial>
    <visual>
      <origin
        xyz="0 0 0"
        rpy="0 0 0" />
      <geometry>
        <mesh
          filename="package://max_waist/meshes/HR1.STL" />
      </geometry>
      <material
        name="">
        <color
          rgba="0.16 0.14 0.13 1" />
      </material>
    </visual>
    <collision>
      <origin
        xyz="0 0 0"
        rpy="0 0 0" />
      <geometry>
        <mesh
          filename="package://max_waist/meshes/HR1.STL" />
      </geometry>
    </collision>
  </link>

  <joint
    name="joint_HR1"
    type="revolute">
    <origin
      xyz="-0.1145 -0.059 0"
      rpy="0 0 0" />
    <parent
      link="body_h" />
    <child
      link="HR1" />
    <axis
      xyz="1 0 0" />
    <limit
      lower="-3.14"
      upper="3.14"
      effort="0"
      velocity="0" />
  </joint>

  <link
    name="HR2">
    <inertial>
      <origin
        xyz="-0.00079198 0.02743131 -0.02361734"
        rpy="0 0 0" />
      <mass
        value="0.89043408" />
      <inertia
        ixx="0.00366698"
        ixy="0.00004816"
        ixz="-0.00007841"
        iyy="0.00417229"
        iyz="0.00046644"
        izz="0.00119996" />
    </inertial>
    <visual>
      <origin
        xyz="0 0 0"
        rpy="0 0 0" />
      <geometry>
        <mesh
          filename="package://max_waist/meshes/HR2.STL" />
      </geometry>
      <material
        name="">
        <color
          rgba="1 1 1 1" />
      </material>
    </visual>
    <collision>
      <origin
        xyz="0 0 0"
        rpy="0 0 0" />
      <geometry>
        <mesh
          filename="package://max_waist/meshes/HR2.STL" />
      </geometry>
    </collision>
  </link>

  <joint
    name="joint_HR2"
    type="revolute">
    <origin
      xyz="0 -0.0892499796735983 0"
      rpy="0 0 0" />
    <parent
      link="HR1" />
    <child
      link="HR2" />
    <axis
      xyz="0 -1 0" />
    <limit
      lower="-3.14"
      upper="3.14"
      effort="0"
      velocity="0" />
  </joint>

  <link
    name="HR3">
    <inertial>
      <origin
        xyz="0.00259104 0.00000184 -0.06944705"
        rpy="0 0 0" />
      <mass
        value="0.28839466" />
      <inertia
        ixx="0.00208365"
        ixy="-0.00000003"
        ixz="0.00003860"
        iyy="0.00209717"
        iyz="-0.00000237"
        izz="0.00006282" />
    </inertial>
    <visual>
      <origin
        xyz="0 0 0"
        rpy="0 0 0" />
      <geometry>
        <mesh
          filename="package://max_waist/meshes/HR3.STL" />
      </geometry>
      <material
        name="">
        <color
          rgba="0.16 0.14 0.13 1" />
      </material>
    </visual>
    <collision>
      <origin
        xyz="0 0 0"
        rpy="0 0 0" />
      <geometry>
        <mesh
          filename="package://max_waist/meshes/HR3.STL" />
      </geometry>
    </collision>
  </link>

  <joint
    name="joint_HR3"
    type="revolute">
    <origin
      xyz="0 0 -0.211499999999999"
      rpy="0 0.0600798924408567 0" />
    <parent
      link="HR2" />
    <child
      link="HR3" />
    <axis
      xyz="0 -1 0" />
    <limit
      lower="-3.14"
      upper="3.14"
      effort="0"
      velocity="0" />
  </joint>

  <link
    name="HRW">
    <inertial>
      <origin
        xyz="0 -0.00744685 0"
        rpy="0 0 0" />
      <mass
        value="0.18058613" />
      <inertia
        ixx="0.00008260"
        ixy="0"
        ixz="0"
        iyy="0.00014146"
        iyz="0"
        izz="0.00008260" />
    </inertial>
    <visual>
      <origin
        xyz="0 0 0"
        rpy="0 0 0" />
      <geometry>
        <mesh
          filename="package://max_waist/meshes/HRW.STL" />
      </geometry>
      <material
        name="">
        <color
          rgba="0.16 0.14 0.13 1" />
      </material>
    </visual>
    <collision>
      <origin
        xyz="0 0 0"
        rpy="0 0 0" />
      <geometry>
        <mesh
          filename="package://max_waist/meshes/HRW.STL" />
      </geometry>
    </collision>
  </link>

  <joint
    name="joint_HRW"
    type="continuous">
    <origin
      xyz="0 -0.0403500231257845 -0.211499999999999"
      rpy="0 -0.00847999366638611 0" />
    <parent
      link="HR2" />
    <child
      link="HRW" />
    <axis
      xyz="0 -1 0" />
  </joint>

  <link
    name="HL1">
    <inertial>
      <origin
        xyz="0.00286541 -0.000331671 -0.00046653"
        rpy="0 0 0" />
      <mass
        value="0.60318142" />
      <inertia
        ixx="0.00036534"
        ixy="-0.00000156"
        ixz="0.00000493"
        iyy="0.00064755"
        iyz="-0.00000517"
        izz="0.00041528" />
    </inertial>
    <visual>
      <origin
        xyz="0 0 0"
        rpy="0 0 0" />
      <geometry>
        <mesh
          filename="package://max_waist/meshes/HL1.STL" />
      </geometry>
      <material
        name="">
        <color
          rgba="0.16 0.14 0.13 1" />
      </material>
    </visual>
    <collision>
      <origin
        xyz="0 0 0"
        rpy="0 0 0" />
      <geometry>
        <mesh
          filename="package://max_waist/meshes/HL1.STL" />
      </geometry>
    </collision>
  </link>

  <joint
    name="joint_HL1"
    type="revolute">
    <origin
      xyz="-0.1145 0.059 0"
      rpy="0 0 0" />
    <parent
      link="body_h" />
    <child
      link="HL1" />
    <axis
      xyz="1 0 0" />
    <limit
      lower="-3.14"
      upper="3.14"
      effort="0"
      velocity="0" />
  </joint>

  <link
    name="HL2">
    <inertial>
      <origin
        xyz="0.00119740 -0.02723755 -0.02392711"
        rpy="0 0 0" />
      <mass
        value="0.89043408" />
      <inertia
        ixx="0.00366698"
        ixy="0.00004816"
        ixz="0.00007841"
        iyy="0.00417229"
        iyz="-0.00046644"
        izz="0.00119996" />
    </inertial>
    <visual>
      <origin
        xyz="0 0 0"
        rpy="0 0 0" />
      <geometry>
        <mesh
          filename="package://max_waist/meshes/HL2.STL" />
      </geometry>
      <material
        name="">
        <color
          rgba="1 1 1 1" />
      </material>
    </visual>
    <collision>
      <origin
        xyz="0 0 0"
        rpy="0 0 0" />
      <geometry>
        <mesh
          filename="package://max_waist/meshes/HL2.STL" />
      </geometry>
    </collision>
  </link>

  <joint
    name="joint_HL2"
    type="revolute">
    <origin
      xyz="0 0.08925 0"
      rpy="0 0 0" />
    <parent
      link="HL1" />
    <child
      link="HL2" />
    <axis
      xyz="0 -1 0" />
    <limit
      lower="-3.14"
      upper="3.14"
      effort="0"
      velocity="0" />
  </joint>

  <link
    name="HL3">
    <inertial>
       <origin
        xyz="0.00259104 0.00033118 -0.06944705"
        rpy="0 0 0" />
      <mass
        value="0.28839466" />
      <inertia
        ixx="0.00208365"
        ixy="-0.00000003"
        ixz="-0.00003860"
        iyy="0.00209717"
        iyz="0.00000237"
        izz="0.00006282" />
    </inertial>
    <visual>
      <origin
        xyz="0 0 0"
        rpy="0 0 0" />
      <geometry>
        <mesh
          filename="package://max_waist/meshes/HL3.STL" />
      </geometry>
      <material
        name="">
        <color
          rgba="0.16 0.14 0.13 1" />
      </material>
    </visual>
    <collision>
      <origin
        xyz="0 0 0"
        rpy="0 0 0" />
      <geometry>
        <mesh
          filename="package://max_waist/meshes/HL3.STL" />
      </geometry>
    </collision>
  </link>

  <joint
    name="joint_HL3"
    type="revolute">
    <origin
      xyz="0 0 -0.2115"
      rpy="0 0.06008 0" />
    <parent
      link="HL2" />
    <child
      link="HL3" />
    <axis
      xyz="0 -1 0" />
    <limit
      lower="-3.14"
      upper="3.14"
      effort="0"
      velocity="0" />
  </joint>

  <link
    name="HLW">
    <inertial>
      <origin
         xyz="0 0.00744685 0"
        rpy="0 0 0" />
      <mass
        value="0.18058613" />
      <inertia
        ixx="0.00008260"
        ixy="0"
        ixz="0"
        iyy="0.00014146"
        iyz="0"
        izz="0.00008260" />
    </inertial>
    <visual>
      <origin
        xyz="0 0 0"
        rpy="0 0 0" />
      <geometry>
        <mesh
          filename="package://max_waist/meshes/HLW.STL" />
      </geometry>
      <material
        name="">
        <color
          rgba="0.16 0.14 0.13 1" />
      </material>
    </visual>
    <collision>
      <origin
        xyz="0 0 0"
        rpy="0 0 0" />
      <geometry>
        <mesh
          filename="package://max_waist/meshes/HLW.STL" />
      </geometry>
    </collision>
  </link>

  <joint
    name="joint_HLW"
    type="continuous">
    <origin
      xyz="0 0.04035 -0.2115"
      rpy="0 0.025975 0" />
    <parent
      link="HL2" />
    <child
      link="HLW" />
    <axis
      xyz="0 -1 0" />
  </joint>

  <link
    name="tail1">
    <inertial>
      <origin
        xyz="-0.00720997 0 0"
        rpy="0 0 0" />
      <mass
        value="0.02032553" />
      <inertia
        ixx="0.00000148"
        ixy="0"
        ixz="0"
        iyy="0.00000119"
        iyz="0"
        izz="0.00000119" />
    </inertial>
    <visual>
      <origin
        xyz="0 0 0"
        rpy="0 0 0" />
      <geometry>
        <mesh
          filename="package://max_waist/meshes/tail1.STL" />
      </geometry>
      <material
        name="">
        <color
          rgba="1 1 1 1" />
      </material>
    </visual>
    <collision>
      <origin
        xyz="0 0 0"
        rpy="0 0 0" />
      <geometry>
        <mesh
          filename="package://max_waist/meshes/tail1.STL" />
      </geometry>
    </collision>
  </link>

  <joint
    name="joint_tail1"
    type="revolute">
    <origin
      xyz="-0.06884 0 0.03401"
      rpy="0 0.5236 0" />
    <parent
      link="body_h" />
    <child
      link="tail1" />
    <axis
      xyz="1 0 0" />
    <limit
      lower="-3.14"
      upper="3.14"
      effort="0"
      velocity="0" />
  </joint>

  <link
    name="tail2">
    <inertial>
      <origin
       xyz="-0.01004380 0 0"
        rpy="0 0 0" />
      <mass
        value="0.02974925" />
      <inertia
        ixx="0.00000367"
        ixy="0"
        ixz="0"
        iyy="0.00000309"
        iyz="0"
        izz="0.00000308" />
    </inertial>
    <visual>
      <origin
        xyz="0 0 0"
        rpy="0 0 0" />
      <geometry>
        <mesh
          filename="package://max_waist/meshes/tail2.STL" />
      </geometry>
      <material
        name="">
        <color
          rgba="0.16 0.14 0.13 1" />
      </material>
    </visual>
    <collision>
      <origin
        xyz="0 0 0"
        rpy="0 0 0" />
      <geometry>
        <mesh
          filename="package://max_waist/meshes/tail2.STL" />
      </geometry>
    </collision>
  </link>

  <joint
    name="joint_tail2"
    type="revolute">
    <origin
      xyz="-0.017665 0 0"
      rpy="0 0 0" />
    <parent
      link="tail1" />
    <child
      link="tail2" />
    <axis
      xyz="0 0 1" />
    <limit
      lower="-3.14"
      upper="3.14"
      effort="0"
      velocity="0" />
  </joint>

  <link
    name="tail3">
    <inertial>
      <origin
        xyz="-0.07963213 0.00245594 -0.01893095"
        rpy="0 0 0" />
      <mass
        value="0.11306774" />
      <inertia
        ixx="0.00003343"
        ixy="-0.00000872"
        ixz="0.00007845"
        iyy="0.00035733"
        iyz="-0.00000213"
        izz="0.00033013" />
    </inertial>
    <visual>
      <origin
        xyz="0 0 0"
        rpy="0 0 0" />
      <geometry>
        <mesh
          filename="package://max_waist/meshes/tail3.STL" />
      </geometry>
      <material
        name="">
        <color
          rgba="0.24 0.35 0.67 1" />
      </material>
    </visual>
    <collision>
      <origin
        xyz="0 0 0"
        rpy="0 0 0" />
      <geometry>
        <mesh
          filename="package://max_waist/meshes/tail3.STL" />
      </geometry>
    </collision>
  </link>

  <joint
    name="joint_tail3"
    type="revolute">
    <origin
      xyz="-0.020571 0 0"
      rpy="0 -0.20556 0" />
    <parent
      link="tail2" />
    <child
      link="tail3" />
    <axis
      xyz="0 -1 0" />
    <limit
      lower="-3.14"
      upper="3.14"
      effort="0"
      velocity="0" />
  </joint>

  <link
    name="tail4">
    <inertial>
      <origin
         xyz="-0.03399007 0.00144785 -0.01179413"
        rpy="0 0 0" />
      <mass
        value="0.06080974" />
      <inertia
        ixx="0.00000344"
        ixy="-0.00000192"
        ixz="0.00000862"
        iyy="0.00004158"
        iyz="-0.00000040"
        izz="0.00003930" />
    </inertial>
    <visual>
      <origin
        xyz="0 0 0"
        rpy="0 0 0" />
      <geometry>
        <mesh
          filename="package://max_waist/meshes/tail4.STL" />
      </geometry>
      <material
        name="">
        <color
          rgba="0.24 0.35 0.67 1" />
      </material>
    </visual>
    <collision>
      <origin
        xyz="0 0 0"
        rpy="0 0 0" />
      <geometry>
        <mesh
          filename="package://max_waist/meshes/tail4.STL" />
      </geometry>
    </collision>
  </link>

  <joint
    name="joint_tail4"
    type="revolute">
    <origin
      xyz="-0.19328 0.0055 -0.072031"
      rpy="0 0.032071 0" />
    <parent
      link="tail3" />
    <child
      link="tail4" />
    <axis
      xyz="0 -1 0" />
    <limit
      lower="-3.14"
      upper="3.14"
      effort="0"
      velocity="0" />
  </joint>

</robot>